<mujoco model="Wheel_legged_description">
  <compiler angle="radian" meshdir="../meshes_display/" autolimits="true"/>
    <size njmax="500" nconmax="100" />
    <option timestep="0.001" iterations="50" solver="PGS" gravity="0 0 -9.81" noslip_iterations="20">
    </option>
    <default>
      <geom contype="1" conaffinity="1" condim="1" solref="0.005 1"/>
    </default>
    <visual>
      <quality shadowsize="4096"/>
      <global realtime="1"/>
    </visual>
    <asset>
      <texture type="skybox" builtin="gradient" rgb1="0.3 0.5 0.7" rgb2="0 0 0" width="512" height="512"/>
      <texture name="texplane" type="2d" builtin="checker" rgb1=".2 .3 .4" rgb2=".1 0.15 0.2"
        width="512" height="512" mark="cross" markrgb=".8 .8 .8"/>
      <texture name="texplane2" type="2d" builtin="checker" rgb1="1 0.3137 0.1843" rgb2="0.0 0.30196 0.38039"
        width="512" height="512" mark="cross" markrgb=".8 .8 .8"/>

      <material name="matplane" reflectance="0." texture="texplane" texrepeat="1 1" texuniform="true"/>
      <material name="matplane2" reflectance="0.1" texture="texplane2" texrepeat="1 1" texuniform="true"/>
      <material name='obstacle'  rgba='0.9 0.6 0.2 1'/>
      <material name='visualgeom'  rgba='0.5 0.9 0.2 1'/>
      <material name='visualgeom2'  rgba='0.5 0.9 0.2 1'/>
    	<mesh name="base_link" file="base_link.STL"/>
   	  <mesh name="waist_Link" file="waist_Link.STL"/>
    	<mesh name="Labad_Link" file="Labad_Link.STL"/>
    	<mesh name="Lhip_Link" file="Lhip_Link.STL"/>
    	<mesh name="Lknee_Link" file="Lknee_Link.STL"/>
    	<mesh name="Rabad_Link" file="Rabad_Link.STL"/>
    	<mesh name="Rhip_Link" file="Rhip_Link.STL"/>
    	<mesh name="Rknee_Link" file="Rknee_Link.STL"/>
    	<mesh name="LF_hip_Link" file="LF_hip_Link.STL"/>
    	<mesh name="LF_knee_Link" file="LF_knee_Link.STL"/>
    	<mesh name="Lwheel_Link" file="Lwheel_Link.STL"/>
    	<mesh name="LB_hip_Link" file="LB_hip_Link.STL"/>
    	<mesh name="LB_knee_Link" file="LB_knee_Link.STL"/>
    	<mesh name="RF_hip_Link" file="RF_hip_Link.STL"/>
    	<mesh name="RF_knee_Link" file="RF_knee_Link.STL"/>
    	<mesh name="Rwheel_Link" file="Rwheel_Link.STL"/>
    	<mesh name="RB_hip_Link" file="RB_hip_Link.STL"/>
    	<mesh name="RB_knee_Link" file="RB_knee_Link.STL"/>
  </asset>
  <worldbody>
    <light directional="false" cutoff="60" exponent="1" diffuse=".5 .5 .5" specular=".1 .1 .1" pos="0.5 0.1 0.8" dir="-0.5 -0.1 -0.8"/>
    <geom name="ground" type="plane" size="0 0 1" pos="0.01 0 -0.285" quat="1 0 0 0" material="matplane" condim="3" contype="15" conaffinity='0' friction="1.2 0.8 0.8"/>
    <body name="base_link" pos="0 0 0.5">
      <freejoint/>
      <inertial pos="0.1015927041891579 0.00071509554661818 0.0289337663641155" quat="1 0 0 0" mass="16.8740" diaginertia="0.29867 0.48858 0.65671 " />
      <geom type="mesh" contype="0" conaffinity="0" group="1" density="0" rgba="0.529412 0.54902 0.54902 1" mesh="base_link"/>
      <geom size="0.14 0.165 0.1065" pos="0 0 0.02" type="box" rgba="0.529412 0.54902 0.54902 0"/>
      <geom size="0.0075 0.0075 0.002" type="box" contype="0" conaffinity="0" group="1" density="0"/>
      <geom pos="0.000107024 0.00535894 0.0709154" type="mesh" contype="0" conaffinity="0" group="1" density="0" rgba="0.792157 0.819608 0.933333 1" mesh="waist_Link"/>
      <geom size="0.28 0.12 0.05" pos="0.280107 0.00535894 0.0709154" type="box" rgba="0.792157 0.819608 0.933333 0"/>
      <site name="base_imu" pos="0.08 0 0.02" type="box" size="0.01 0.01 0.01" rgba="0.8 0.8 0.8 0.5"/>
      <!-- <point> -->
      <body name="LF_hip_Link" pos="0.060111 0.191429 0.0692325" gravcomp="0">
        <inertial pos="0.0615859 -0.000613058 -0.0390776" quat="0.32077 0.657207 0.586274 0.348524" mass="0.177077" diaginertia="0.00070071 0.000647868 6.14221e-05"/>
        <joint name="Joint_LFhip" pos="0 0 0" axis="0 1 0" limited="true" range="-0.93 0.45" damping="0.01" frictionloss="0.01" armature="0.01"/>
        <geom type="mesh" contype="0" conaffinity="0" group="1" density="0" rgba="1 1 1 1" mesh="LF_hip_Link"/>
        <geom size="0.1 0.01 0.025" pos="0.06 0 -0.04" quat="0.955336 0 0.29552 0" type="box" rgba="1 1 1 0"/>
        <body name="LF_knee_Link" pos="0.124002 0.00618 -0.0847037" gravcomp="0">
          <inertial pos="-0.097663 0.0140473 -0.104843" quat="-0.259341 0.657831 0.657831 -0.259341" mass="0.280637" diaginertia="0.00225442 0.00220135 5.84701e-05"/>
          <joint name="Joint_LFknee" pos="0 0 0" axis="0 1 0" limited="true" range="-0.685 1.04"/>
          <geom type="mesh" contype="0" conaffinity="0" group="1" density="0" rgba="1 1 1 1" mesh="LF_knee_Link"/>
          <geom type="mesh" rgba="1 1 1 1" mesh="LF_knee_Link"/>
          <geom size="0.02" pos="-0.18 0.04 -0.27" contype="0" conaffinity="0" group="1" density="0" rgba="0.529412 0.54902 0.54902 1"/>
          <geom size="0.02" pos="-0.18 0.04 -0.27" rgba="0.529412 0.54902 0.54902 1"/>
          <!-- <body name="laxis" pos="-0.17978 0.0402 -0.20147" gravcomp="0">
            <inertial pos="-3.0131e-05 -0.011025 4.8139e-05" quat="0.820473 0.339851 -0.17592 0.424708" mass="0.001" diaginertia="1e-09 1e-09 1e-09"/>
            <joint name="Joint_laxis" pos="0 0 0" axis="0 1 0"/>
            <geom size="0.005 0.025" pos="0 -0.045 0" quat="0.5 -0.5 0.5 0.5" type="cylinder" contype="0" conaffinity="0" group="1" density="0" rgba="0 0 0 1"/> -->
            <body name="Lwheel_Link" pos="-0.17978 0.0402 -0.20147" gravcomp="0">
              <inertial pos="0.00010458 -0.011045 -3.7866e-05" quat="0.707107 0 0 0.707107" mass="0.825401" diaginertia="0.00186 0.00145 0.00145"/>
              <!-- <joint name="Joint_LWheel" pos="0 0 0" axis="0 1 0"/> -->
              <geom type="mesh" contype="0" conaffinity="0" group="1" density="0" rgba="0.792157 0.819608 0.933333 1" mesh="Lwheel_Link"/>
              <geom size="0.09 0.02" quat="0.707388 0.706825 0 0" type="cylinder" rgba="0.792157 0.819608 0.933333 0"/>
            </body>
          <!-- </body> -->
        </body>
      </body>
      <body name="LB_hip_Link" pos="-0.0598897 0.194429 0.0686073" gravcomp="0">
        <inertial pos="-0.0590005 -0.00341205 -0.038742" quat="0.657207 0.32077 0.348524 0.586274" mass="0.18" diaginertia="0.00070071 0.000647868 6.14221e-05"/>
        <joint name="Joint_LBhip" pos="0 0 0" axis="0 1 0" limited="true" range="-0.45 0.93" damping="0.01" frictionloss="0.01" armature="0.01"/>
        <geom type="mesh" contype="0" conaffinity="0" group="1" density="0" rgba="1 1 1 1" mesh="LB_hip_Link"/>
        <geom type="mesh" rgba="1 1 1 1" mesh="LB_hip_Link"/>
        <body name="LB_knee_Link" pos="-0.120708 -0.00732 -0.0887404" gravcomp="0">
          <inertial pos="0.091245 -0.00700003 -0.097323" quat="0.657831 -0.259341 -0.259341 0.657831" mass="0.225121" diaginertia="0.00225442 0.00220135 5.84701e-05"/>
          <joint name="Joint_LBknee" pos="0 0 0" axis="0 1 0" limited="true" range="-1.04 0.685"/>
          <geom type="mesh" contype="0" conaffinity="0" group="1" density="0" rgba="1 1 1 1" mesh="LB_knee_Link"/>
          <geom type="mesh" rgba="1 1 1 1" mesh="LB_knee_Link"/>
        </body>
      </body>
      <body name="RF_hip_Link" pos="0.0601109 -0.186391 0.0686016" gravcomp="0">
        <inertial pos="0.0720854 0.000793069 -0.0477055" quat="0.32077 0.657207 0.586274 0.348524" mass="0.177077" diaginertia="0.00070071 0.000647868 6.14221e-05"/>
        <joint name="Joint_RFhip" pos="0 0 0" axis="0 1 0" limited="true" range="-0.93 0.45" damping="0.01" frictionloss="0.01" armature="0.01"/>
        <geom type="mesh" contype="0" conaffinity="0" group="1" density="0" rgba="1 1 1 1" mesh="RF_hip_Link"/>
        <geom type="mesh" rgba="1 1 1 1" mesh="RF_hip_Link"/>
        <body name="RF_knee_Link" pos="0.124791 -0.006 -0.0829024" gravcomp="0">
          <inertial pos="-0.097368 -0.0100073 -0.105112" quat="-0.259341 0.657831 0.657831 -0.259341" mass="0.280637" diaginertia="0.00225442 0.00220135 5.84701e-05"/>
          <joint name="Joint_RFknee" pos="0 0 0" axis="0 1 0" limited="true" range="-0.685 1.04"/>
          <geom type="mesh" contype="0" conaffinity="0" group="1" density="0" rgba="1 1 1 1" mesh="RF_knee_Link"/>
          <geom type="mesh" rgba="1 1 1 1" mesh="RF_knee_Link"/>
          <geom size="0.02" pos="-0.18 -0.04 -0.27" contype="0" conaffinity="0" group="1" density="0" rgba="0.529412 0.54902 0.54902 1"/>
          <geom size="0.02" pos="-0.18 -0.04 -0.27" rgba="0.529412 0.54902 0.54902 1"/>
          <!-- <body name="raxis" pos="-0.180075 -0.0402 -0.20123" gravcomp="0">
            <inertial pos="5.4339e-05 0.011025 -1.65e-05" quat="0.820473 0.339851 -0.17592 0.424708" mass="0.001" diaginertia="1e-09 1e-09 1e-09"/>
            <joint name="Joint_raxis" pos="0 0 0" axis="0 1 0"/>
            <geom size="0.005 0.025" pos="0 0.045 0" quat="0.5 -0.5 0.5 0.5" type="cylinder" contype="0" conaffinity="0" group="1" density="0" rgba="0 0 0 1"/> -->
            <body name="Rwheel_Link" pos="-0.180075 -0.0402 -0.20123" gravcomp="0">
              <inertial pos="0.00010458 0.0110455 -3.7866e-05" quat="0.707107 0 0 0.707107" mass="0.825401" diaginertia="0.00186 0.00145 0.00145"/>
              <!-- <joint name="Joint_RWheel" pos="0 0 0" axis="0 1 0"/> -->
              <geom type="mesh" contype="0" conaffinity="0" group="1" density="0" rgba="0.792157 0.819608 0.933333 1" mesh="Rwheel_Link"/>
              <geom size="0.09 0.02" quat="0.707388 0.706825 0 0" type="cylinder" rgba="0.792157 0.819608 0.933333 0"/>
          </body>
        </body>
      </body>
      <body name="RB_hip_Link" pos="-0.0598897 -0.189391 0.0692432" gravcomp="0">
        <inertial pos="-0.061051 0.00059178 -0.046907" quat="0.657207 0.32077 0.348524 0.586274" mass="0.18" diaginertia="0.00070071 0.000647868 6.14221e-05"/>
        <joint name="Joint_RBhip" pos="0 0 0" axis="0 1 0" limited="true" range="-0.45 0.93" damping="0.01" frictionloss="0.01" armature="0.01"/>
        <geom type="mesh" contype="0" conaffinity="0" group="1" density="0" rgba="1 1 1 1" mesh="RB_hip_Link"/>
        <geom type="mesh" rgba="1 1 1 1" mesh="RB_hip_Link"/>
        <body name="RB_knee_Link" pos="-0.121051 0.0075 -0.0889105" gravcomp="0">
          <inertial pos="0.0919309 0.00700003 -0.0966663" quat="0.656351 -0.263066 -0.263066 0.656351" mass="0.225121" diaginertia="0.00225442 0.00220135 5.84701e-05"/>
          <joint name="Joint_RBknee" pos="0 0 0" axis="0 1 0" limited="true" range="-1.04 0.685"/>
          <geom type="mesh" contype="0" conaffinity="0" group="1" density="0" rgba="1 1 1 1" mesh="RB_knee_Link"/>
          <geom type="mesh" rgba="1 1 1 1" mesh="RB_knee_Link"/>
        </body>
      </body>
      <body name="Labad_Link" pos="0.56018 0.105785 0.0331767" gravcomp="0">
        <inertial pos="-0.00595687 -0.0107941 -0.000171966" quat="0.506339 0.492985 -0.502862 0.497711" mass="1.27" diaginertia="0.00270 0.00284 0.00162"/>
        <joint name="Joint_Labad" pos="0 0 0" axis="1 0 0" limited="true" range="-0.424 1.04" damping="0.01" frictionloss="0.01" armature="0.01"/>
        <geom type="mesh" contype="0" conaffinity="0" group="1" density="0" rgba="1 1 1 1" mesh="Labad_Link"/>
        <geom size="0.048 0.065" quat="0.707388 0.706825 0 0" type="cylinder" rgba="0.792157 0.819608 0.933333 0"/>
        <body name="Lhip_Link" pos="-0.000174443 0.0776923 0.00019391" gravcomp="0">
          <inertial pos="-0.000723234 -0.00460421 -0.0865058" quat="0.705137 0.0170159 -0.013058 0.708747" mass="1.02" diaginertia="0.00994 0.00953 0.00079"/>
          <joint name="Joint_Lhip" pos="0 0 0" axis="0 1 0" limited="true" range="-0.503 1.41" damping="0.01" frictionloss="0.01" armature="0.01"/>
          <geom type="mesh" contype="0" conaffinity="0" group="1" density="0" rgba="0.792157 0.819608 0.933333 1" mesh="Lhip_Link"/>
          <geom size="0.05 0.02 0.115" pos="0 0 -0.115" type="box" rgba="0.792157 0.819608 0.933333 0"/>
          <body name="Lknee_Link" pos="-0.00165862 0.031407 -0.230048" gravcomp="0">
            <inertial pos="-0.00190486 -4.3168e-06 -0.12757" quat="0.560944 0.0139705 -0.00976398 0.827678" mass="0.24" diaginertia="0.00159 0.00159 0.00003"/>
            <joint name="Joint_Lknee" pos="0 0 0" axis="0 1 0" limited="true" range="-3.14 0" damping="0.01" frictionloss="0.01" armature="0.01"/>
            <geom type="mesh" contype="0" conaffinity="0" group="1" density="0" rgba="0.792157 0.819608 0.933333 1" mesh="Lknee_Link"/>
            <geom size="0.02 0.125" pos="0 0 -0.125" type="cylinder" rgba="0.792157 0.819608 0.933333 0"/>
            <!-- <geom size="0.02" pos="-0.0025 0.002 -0.232" contype="0" conaffinity="0" group="1" density="0" rgba="0.529412 0.54902 0.54902 1"/>
            <geom size="0.02" pos="-0.0025 0.002 -0.232" rgba="0.529412 0.54902 0.54902 1"/> -->
          </body>
        </body>
      </body>
      <body name="Rabad_Link" pos="0.56008 -0.10775 0.0316767" gravcomp="0">
        <inertial pos="-0.00605932 0.0107735 0.000594366" quat="0.506339 0.492985 -0.502862 0.497711" mass="1.27" diaginertia="0.00270 0.00284 0.00162"/>
        <joint name="Joint_Rabad" pos="0 0 0" axis="1 0 0" limited="true" range="-1.04 0.424" damping="0.01" frictionloss="0.01" armature="0.01"/>
        <geom type="mesh" contype="0" conaffinity="0" group="1" density="0" rgba="1 1 1 1" mesh="Rabad_Link"/>
        <geom size="0.048 0.065" quat="0.707388 0.706825 0 0" type="cylinder" rgba="0.792157 0.819608 0.933333 0"/>
        <body name="Rhip_Link" pos="-7.14114e-05 -0.0767142 0.000899685" gravcomp="0">
          <inertial pos="-0.000328071 0.00342242 -0.0865492" quat="0.708814 -0.0138294 0.0177784 0.705035" mass="1.02" diaginertia="0.00994 0.00953 0.00079"/>
          <joint name="Joint_Rhip" pos="0 0 0" axis="0 1 0" limited="true" range="-0.503 1.41" damping="0.01" frictionloss="0.01" armature="0.01"/>
          <geom type="mesh" contype="0" conaffinity="0" group="1" density="0" rgba="0.792157 0.819608 0.933333 1" mesh="Rhip_Link"/>
          <geom size="0.05 0.02 0.115" pos="0 0 -0.115" type="box" rgba="0.792157 0.819608 0.933333 0"/>
          <body name="Rknee_Link" pos="-0.0011405 -0.0323891 -0.229762" gravcomp="0">
            <inertial pos="-0.00519458 -0.000601366 -0.127715" quat="0.924397 -0.00799365 0.0202102 0.380812" mass="0.24" diaginertia="0.00159 0.00159 0.00003"/>
            <joint name="Joint_Rknee" pos="0 0 0" axis="0 1 0" limited="true" range="-3.14 0" damping="0.01" frictionloss="0.01" armature="0.01"/>
            <geom type="mesh" contype="0" conaffinity="0" group="1" density="0" rgba="0.792157 0.819608 0.933333 1" mesh="Rknee_Link"/>
            <geom size="0.02 0.125" pos="0 0 -0.125" type="cylinder" rgba="0.792157 0.819608 0.933333 0"/>
            <!-- <geom size="0.02" pos="-0.007 -0.002 -0.232" contype="0" conaffinity="0" group="1" density="0" rgba="0.529412 0.54902 0.54902 1"/>
            <geom size="0.02" pos="-0.007 -0.002 -0.232" rgba="0.529412 0.54902 0.54902 1"/> -->
          </body>
        </body>
      </body>
    </body>
  </worldbody>

  <equality>
    <connect body1="LF_knee_Link" body2="LB_knee_Link" anchor="-0.211059 0.01 -0.183995" solimp="0.9 0.95 0.001 0.1 10" solref="0.01 0.1"/>
    <connect body1="RF_knee_Link" body2="RB_knee_Link" anchor="-0.211059 0.01 -0.183995" solimp="0.9 0.95 0.001 0.1 10" solref="0.01 0.1"/>
  </equality>

  <actuator>
    <motor name="A8112-1" joint="Joint_LFhip" gear="1" ctrllimited="true" ctrlrange="-100 100"/>
    <motor name="A8112-2" joint="Joint_LBhip" gear="1" ctrllimited="true" ctrlrange="-100 100"/>
    <!-- <motor name="M9025-1" joint="Joint_LWheel" gear="1" ctrllimited="true" ctrlrange="-30 30"/> -->
    <motor name="A8112-3" joint="Joint_RFhip" gear="1" ctrllimited="true" ctrlrange="-100 100"/>
    <motor name="A8112-4" joint="Joint_RBhip" gear="1" ctrllimited="true" ctrlrange="-100 100"/>
    <!-- <motor name="A8112-5" joint="Joint4" gear="1" ctrllimited="true" ctrlrange="-100 100"/> -->
    <!-- <motor name="M9025-2" joint="Joint_RWheel" gear="1" ctrllimited="true" ctrlrange="-30 30"/> -->
    <motor name="DM1" joint="Joint_Labad" gear="1" ctrllimited="true" ctrlrange="-50 50"/>
    <motor name="DM2" joint="Joint_Lhip"  gear="1" ctrllimited="true" ctrlrange="-50 50"/>
    <motor name="DM3" joint="Joint_Lknee" gear="1" ctrllimited="true" ctrlrange="-50 50"/>
    <motor name="DM4" joint="Joint_Rabad" gear="1" ctrllimited="true" ctrlrange="-50 50"/>
    <motor name="DM5" joint="Joint_Rhip"  gear="1" ctrllimited="true" ctrlrange="-50 50"/>
    <motor name="DM6" joint="Joint_Rknee" gear="1" ctrllimited="true" ctrlrange="-50 50"/>
  </actuator>

  <sensor>
    <!-- <actuatorpos name="waist_pos"         actuator="A8112-1" noise="0.01"/> -->
    <jointpos name="Lf_motor_pos"   joint="Joint_LFhip"/>
    <jointpos name="Lb_motor_pos"   joint="Joint_LBhip"/>
    <!-- <actuatorpos name="Lwheel_pos"     actuator="M9025-1" noise="0.01"/> -->
    <jointpos name="Rf_motor_pos"   joint="Joint_RFhip"/>
    <jointpos name="Rb_motor_pos"   joint="Joint_RBhip"/>
    <!-- <actuatorpos name="Rwheel_pos"     actuator="M9025-2" noise="0.01"/> -->

    <jointpos name="Labad_pos"      joint="Joint_Labad"  />
    <jointpos name="Lhip_pos"       joint="Joint_Lhip"   />
    <jointpos name="Lknee_pos"      joint="Joint_Lknee"  />
    <jointpos name="Rabad_pos"      joint="Joint_Rabad"  />
    <jointpos name="Rhip_pos"       joint="Joint_Rhip"   />
    <jointpos name="Rknee_pos"      joint="Joint_Rknee"  />

    <!-- <actuatorvel name="waist_vel"         actuator="A8112-1" noise="0.01"/> -->
    <jointvel name="Lf_motor_vel"   joint="Joint_LFhip"/>
    <jointvel name="Lb_motor_vel"   joint="Joint_LBhip"/>
    <!-- <actuatorvel name="Lwheel_vel"     actuator="M9025-1" noise="0.01"/> -->
    <jointvel name="Rf_motor_vel"   joint="Joint_RFhip"/>
    <jointvel name="Rb_motor_vel"   joint="Joint_RBhip"/>
    <!-- <actuatorvel name="Rwheel_vel"     actuator="M9025-2" noise="0.01"/> -->

    <jointvel name="Labad_vel"      joint="Joint_Labad" />
    <jointvel name="Lhip_vel"       joint="Joint_Lhip"  />
    <jointvel name="Lknee_vel"      joint="Joint_Lknee" />
    <jointvel name="Rabad_vel"      joint="Joint_Rabad" />
    <jointvel name="Rhip_vel"       joint="Joint_Rhip"  />
    <jointvel name="Rknee_vel"      joint="Joint_Rknee" />

    <accelerometer name="BodyAcc" site="base_imu"/>
    <velocimeter name="BodyVel" site="base_imu"/>
    <gyro name="BodyGyro" site="base_imu"/>
    <framepos name="BodyPos" objtype="site" objname="base_imu"/>
    <framequat name="BodyQuat" objtype="site" objname="base_imu"/>
  </sensor>

</mujoco>
