<?xml version="1.0" encoding="utf-8"?>
<!-- This URDF was automatically created by SolidWorks to URDF Exporter! Originally created by Stephen Brawner (brawner@gmail.com) 
     Commit Version: 1.6.0-4-g7f85cfe  Build Version: 1.6.7995.38578
     For more information, please see http://wiki.ros.org/sw_urdf_exporter -->
<robot name="Wheel_legged_sim">
  <gazebo>
    <plugin filename="libwheel_legged_hw_sim.so" name="gazebo_ros_control">
      <robotNamespace>/</robotNamespace>
      <robotParam>wheel_legged_description</robotParam>
      <robotSimType>ocs2/wheel_legged/LeggedHWSim</robotSimType>
    </plugin>
  </gazebo>
  <gazebo>
    <plugin filename="libgazebo_ros_p3d.so" name="p3d_base_controller">
      <alwaysOn>true</alwaysOn>
      <updateRate>1000.0</updateRate>
      <bodyName>base_link</bodyName>
      <topicName>ground_truth/state</topicName>
      <gaussianNoise>0</gaussianNoise>
      <frameName>world</frameName>
      <xyzOffsets>0 0 0</xyzOffsets>
      <rpyOffsets>0 0 0</rpyOffsets>
    </plugin>
  </gazebo>
  <link name="dummy_link">
    </link>
  <joint name="dummy_to_base_link" type="fixed">
    <parent link="dummy_link"/>
    <child link="base_link"/>
    <origin rpy="0 0 0" xyz="0 0 0"/>
  </joint>
  <link
    name="base_link">
    <visual>
      <origin
        xyz="0 0 0"
        rpy="0 0 0" />
      <geometry>
        <mesh
          filename="package://wheel_legged_description/meshes_display/base_link.STL" />
      </geometry>
      <material
        name="">
        <color
          rgba="0.52941 0.54902 0.54902 1" />
      </material>
    </visual>
    <collision>
      <origin
        xyz="0 0 0"
        rpy="0 0 0" />
      <geometry>
        <box size="0.28 0.33 0.213" />
      </geometry>
    </collision>
  </link>
  <joint name="base_to_base_inertia" type="fixed">
        <parent link="base_link"/>
        <child link="base_inertia"/>
        <origin rpy="0 0 0" xyz="0 0 0"/>
  </joint>
  <link name="base_inertia">
      <inertial>
          <origin
            xyz="-0.034923 0.0027299 0.021738"
            rpy="0 0 0" />
          <mass
            value="14.2740" />
          <inertia
            ixx="0.27466"
            ixy="0.00296"
            ixz="0.00836"
            iyy="0.13446"
            iyz="0.00133"
            izz="0.29099" />
      </inertial>
  </link>
      <!-- Imu is fixed to the base link -->
  <joint name="base_imu_joint" type="fixed">
    <origin rpy="0. 0. 0." xyz="0. 0. 0."/>
    <parent link="base_link"/>
    <child link="base_imu"/>
  </joint>
  <!-- Imu link -->
  <link name="base_imu">
    <inertial>
      <mass value="0.01"/>
      <origin rpy="0 0 0" xyz="0 0 0"/>
      <inertia ixx="0.000001" ixy="0" ixz="0" iyy="0.000001" iyz="0" izz="0.000001"/>
    </inertial>
    <visual>
      <origin rpy="0 0 0" xyz="0 0 0"/>
      <geometry>
        <box size="0.015 0.015 0.004"/>
      </geometry>
    </visual>
    <material name="orange">
      <color rgba="255 108 10 255"/>
    </material>
  </link>
  <gazebo reference="base_imu">
    <material>Gazebo/Orange</material>
  </gazebo>
  <gazebo reference="base_imu_joint">
    <disableFixedJointLumping>true</disableFixedJointLumping>
  </gazebo>
  <link
    name="waist_Link">
    <inertial>
      <origin
        xyz="0.31834 -0.0058844 -0.014821"
        rpy="0 0 0" />
      <mass
        value="2.98" />
      <inertia
        ixx="0.02232"
        ixy="0.00027"
        ixz="0.00628"
        iyy="0.08653"
        iyz="-0.00002"
        izz="0.10216" />
    </inertial>
    <visual>
      <origin
        xyz="0 0 0"
        rpy="0 0 0" />
      <geometry>
        <mesh
          filename="package://wheel_legged_description/meshes_display/waist_Link.STL" />
      </geometry>
      <material
        name="">
        <color
          rgba="0.79216 0.81961 0.93333 1" />
      </material>
    </visual>
    <collision>
      <origin
        xyz="0.28 0 0"
        rpy="0 0 0" />
      <geometry>
        <box size="0.56 0.45 0.1" />
      </geometry>
    </collision>
  </link>
  <joint
    name="Joint_waist"
    type="fixed">
    <origin
      xyz="0.00010702 0.0053589 0.070915"
      rpy="0 0 0" />
    <parent
      link="base_link" />
    <child
      link="waist_Link" />
  </joint>
  <link
    name="Labad_Link">
    <inertial>
      <origin
        xyz="-0.0059569 -0.010794 -0.00017197"
        rpy="0 0 0" />
      <mass
        value="1.27" />
      <inertia
        ixx="0.00270"
        ixy="0.00002"
        ixz="0.00000"
        iyy="0.00162"
        iyz="-0.00001"
        izz="0.00284" />
    </inertial>
    <visual>
      <origin
        xyz="0 0 0"
        rpy="0 0 0" />
      <geometry>
        <mesh
          filename="package://wheel_legged_description/meshes_display/Labad_Link.STL" />
      </geometry>
      <material
        name="">
        <color
          rgba="0.79216 0.81961 0.93333 1" />
      </material>
    </visual>
    <collision>
      <origin
        xyz="0 0 0"
        rpy="0 1.57 0" />
      <geometry>
        <cylinder length="0.13" radius="0.048" />
      </geometry>
    </collision>
  </link>
  <joint
    name="Joint_Labad"
    type="revolute">
    <origin
      xyz="0.56007 0.10043 -0.037739"
      rpy="0 0 0" />
    <parent
      link="waist_Link" />
    <child
      link="Labad_Link" />
    <axis
      xyz="1 0 0" />
    <limit
      lower="-0.424"
      upper="1.04"
      effort="24.206"
      velocity="100" />
  </joint>
  <link
    name="Lhip_Link">
    <inertial>
      <origin
        xyz="-0.00072323 -0.0046042 -0.086506"
        rpy="0 0 0" />
      <mass
        value="1.02" />
      <inertia
        ixx="0.00953"
        ixy="0.00000"
        ixz="-0.00005"
        iyy="0.00994"
        iyz="0.00039"
        izz="0.00079" />
    </inertial>
    <visual>
      <origin
        xyz="0 0 0"
        rpy="0 0 0" />
      <geometry>
        <mesh
          filename="package://wheel_legged_description/meshes_display/Lhip_Link.STL" />
      </geometry>
      <material
        name="">
        <color
          rgba="0.79216 0.81961 0.93333 1" />
      </material>
    </visual>
    <collision>
      <origin
        xyz="0 0 -0.115"
        rpy="0 0 0" />
      <geometry>
        <cylinder length="0.23" radius="0.05" />
      </geometry>
    </collision>
  </link>
  <joint
    name="Joint_Lhip"
    type="revolute">
    <origin
      xyz="-0.00017444 0.077692 0.00019391"
      rpy="0 0 0" />
    <parent
      link="Labad_Link" />
    <child
      link="Lhip_Link" />
    <axis
      xyz="0 1 0" />
    <limit
      lower="-0.503"
      upper="1.41"
      effort="22.76"
      velocity="100" />
  </joint>
  <link
    name="Lknee_Link">
    <inertial>
      <origin
        xyz="-0.0017065 -0.00067242 -0.14609"
        rpy="0 0 0" />
      <mass
        value="0.18" />
      <inertia
        ixx="0.00159"
        ixy="0.00000"
        ixz="-0.00002"
        iyy="0.00159"
        iyz="0.00005"
        izz="0.00003" />
    </inertial>
    <visual>
      <origin
        xyz="0 0 0"
        rpy="0 0 0" />
      <geometry>
        <mesh
          filename="package://wheel_legged_description/meshes_display/Lknee_Link.STL" />
      </geometry>
      <material
        name="">
        <color
          rgba="0.79216 0.81961 0.93333 1" />
      </material>
    </visual>
    <collision>
      <origin
        xyz="0 0 -0.125"
        rpy="0 0 0" />
      <geometry>
        <cylinder length="0.25" radius="0.04" />
      </geometry>
    </collision>
  </link>
  <joint
    name="Joint_Lknee"
    type="revolute">
    <origin
      xyz="-0.0016586 0.031407 -0.23005"
      rpy="0 0 0" />
    <parent
      link="Lhip_Link" />
    <child
      link="Lknee_Link" />
    <axis
      xyz="0 1 0" />
    <limit
      lower="-3.14"
      upper="0"
      effort="28"
      velocity="100" />
  </joint>

  <joint dont_collapse="true" name="LF_foot_fixed" type="fixed">
    <origin rpy="0 0 0" xyz="-0.0025 0.002 -0.232"/>
    <parent link="Lknee_Link"/>
    <child link="LF_FOOT"/>
  </joint>
  <link name="LF_FOOT">
    <visual>
      <origin rpy="0 0 0" xyz="0 0 0"/>
      <geometry>
        <sphere radius="0.01"/>
      </geometry>
      <material name=""/>
    </visual>
    <collision>
      <origin rpy="0 0 0" xyz="0 0 0"/>
      <geometry>
        <sphere radius="0.02"/>
      </geometry>
    </collision>
    <inertial>
      <mass value="0.06"/>
      <inertia ixx="9.600000000000001e-06" ixy="0.0" ixz="0.0" iyy="9.600000000000001e-06" iyz="0.0" izz="9.600000000000001e-06"/>
    </inertial>
  </link>
  <gazebo reference="LF_foot_fixed">
    <disableFixedJointLumping>true</disableFixedJointLumping>
  </gazebo>
  <gazebo reference="Labad_Link">
    <mu1>0.2</mu1>
    <mu2>0.2</mu2>
    <material>Gazebo/DarkGrey</material>
  </gazebo>
  <gazebo reference="Lhip_Link">
    <mu1>0.2</mu1>
    <mu2>0.2</mu2>
    <self_collide>0</self_collide>
    <material>Gazebo/DarkGrey</material>
    <kp value="1000000.0"/>
    <kd value="100.0"/>
  </gazebo>
  <gazebo reference="Lknee_Link">
    <mu1>0.6</mu1>
    <mu2>0.6</mu2>
    <self_collide>1</self_collide>
  </gazebo>
  <gazebo reference="LF_FOOT">
    <mu1>0.6</mu1>
    <mu2>0.6</mu2>
    <self_collide>1</self_collide>
    <material>Gazebo/DarkGrey</material>
    <kp value="1000000.0"/>
    <kd value="100.0"/>
  </gazebo>
  
  <transmission name="LF_HAA_tran">
    <type>transmission_interface/SimpleTransmission</type>
    <joint name="Joint_Labad">
      <hardwareInterface>hardware_interface/EffortJointInterface</hardwareInterface>
    </joint>
    <actuator name="LF_HAA_motor">
      <hardwareInterface>hardware_interface/EffortJointInterface</hardwareInterface>
      <mechanicalReduction>1</mechanicalReduction>
    </actuator>
  </transmission>
  <transmission name="LF_HFE_tran">
    <type>transmission_interface/SimpleTransmission</type>
    <joint name="Joint_Lhip">
      <hardwareInterface>hardware_interface/EffortJointInterface</hardwareInterface>
    </joint>
    <actuator name="LF_HFE_motor">
      <hardwareInterface>hardware_interface/EffortJointInterface</hardwareInterface>
      <mechanicalReduction>1</mechanicalReduction>
    </actuator>
  </transmission>
  <transmission name="LF_KFE_tran">
    <type>transmission_interface/SimpleTransmission</type>
    <joint name="Joint_Lknee">
      <hardwareInterface>hardware_interface/EffortJointInterface</hardwareInterface>
    </joint>
    <actuator name="LF_KFE_motor">
      <hardwareInterface>hardware_interface/EffortJointInterface</hardwareInterface>
      <mechanicalReduction>1</mechanicalReduction>
    </actuator>
  </transmission>

  <link
    name="Rabad_Link">
    <inertial>
      <origin
        xyz="-0.0060593 0.010773 0.00059437"
        rpy="0 0 0" />
      <mass
        value="1.27" />
      <inertia
        ixx="0.00270"
        ixy="-0.00002"
        ixz="0.00000"
        iyy="0.00162"
        iyz="0.00001"
        izz="0.00284" />
    </inertial>
    <visual>
      <origin
        xyz="0 0 0"
        rpy="0 0 0" />
      <geometry>
        <mesh
          filename="package://wheel_legged_description/meshes_display/Rabad_Link.STL" />
      </geometry>
      <material
        name="">
        <color
          rgba="0.79216 0.81961 0.93333 1" />
      </material>
    </visual>
    <collision>
      <origin
        xyz="0 0 0"
        rpy="0 1.57 0" />
      <geometry>
        <cylinder length="0.13" radius="0.048" />
      </geometry>
    </collision>
  </link>
  <joint
    name="Joint_Rabad"
    type="revolute">
    <origin
      xyz="0.55997 -0.11311 -0.039239"
      rpy="0 0 0" />
    <parent
      link="waist_Link" />
    <child
      link="Rabad_Link" />
    <axis
      xyz="1 0 0" />
    <limit
      lower="-1.04"
      upper="0.424"
      effort="24.206"
      velocity="100" />
  </joint>
  <link
    name="Rhip_Link">
    <inertial>
      <origin
        xyz="-0.00032807 0.0034224 -0.086549"
        rpy="0 0 0" />
      <mass
        value="1.02" />
      <inertia
        ixx="0.00953"
        ixy="0.00000"
        ixz="-0.00005"
        iyy="0.00994"
        iyz="-0.00041"
        izz="0.00079" />
    </inertial>
    <visual>
      <origin
        xyz="0 0 0"
        rpy="0 0 0" />
      <geometry>
        <mesh
          filename="package://wheel_legged_description/meshes_display/Rhip_Link.STL" />
      </geometry>
      <material
        name="">
        <color
          rgba="0.79216 0.81961 0.93333 1" />
      </material>
    </visual>
    <collision>
      <origin
        xyz="0 0 -0.115"
        rpy="0 0 0" />
      <geometry>
        <cylinder length="0.23" radius="0.05" />
      </geometry>
    </collision>
  </link>
  <joint
    name="Joint_Rhip"
    type="revolute">
    <origin
      xyz="-7.1411E-05 -0.076714 0.00089968"
      rpy="0 0 0" />
    <parent
      link="Rabad_Link" />
    <child
      link="Rhip_Link" />
    <axis
      xyz="0 1 0" />
    <limit
      lower="-0.503"
      upper="1.41"
      effort="22.76"
      velocity="100" />
  </joint>
  <link
    name="Rknee_Link">
    <inertial>
      <origin
        xyz="-0.0045928 -0.00013516 -0.14629"
        rpy="0 0 0" />
      <mass
        value="0.18" />
      <inertia
        ixx="0.00159"
        ixy="0.00000"
        ixz="-0.00005"
        iyy="0.00159"
        iyz="-0.00005"
        izz="0.00003" />
    </inertial>
    <visual>
      <origin
        xyz="0 0 0"
        rpy="0 0 0" />
      <geometry>
        <mesh
          filename="package://wheel_legged_description/meshes_display/Rknee_Link.STL" />
      </geometry>
      <material
        name="">
        <color
          rgba="0.79216 0.81961 0.93333 1" />
      </material>
    </visual>
    <collision>
      <origin
        xyz="0 0 -0.125"
        rpy="0 0 0" />
      <geometry>
        <cylinder length="0.25" radius="0.04" />
      </geometry>
    </collision>
  </link>
  <joint
    name="Joint_Rknee"
    type="revolute">
    <origin
      xyz="-0.0011405 -0.032389 -0.22976"
      rpy="0 0 0" />
    <parent
      link="Rhip_Link" />
    <child
      link="Rknee_Link" />
    <axis
      xyz="0 1 0" />
    <limit
      lower="-3.14"
      upper="0"
      effort="28"
      velocity="100" />
  </joint>
  <joint dont_collapse="true" name="RF_foot_fixed" type="fixed">
    <origin rpy="0 0 0" xyz="-0.007 -0.002 -0.232"/>
    <parent link="Rknee_Link"/>
    <child link="RF_FOOT"/>
  </joint>
  <link name="RF_FOOT">
    <visual>
      <origin rpy="0 0 0" xyz="0 0 0"/>
      <geometry>
        <sphere radius="0.01"/>
      </geometry>
      <material name=""/>
    </visual>
    <collision>
      <origin rpy="0 0 0" xyz="0 0 0"/>
      <geometry>
        <sphere radius="0.01"/>
      </geometry>
    </collision>
    <inertial>
      <mass value="0.06"/>
      <inertia ixx="9.600000000000001e-06" ixy="0.0" ixz="0.0" iyy="9.600000000000001e-06" iyz="0.0" izz="9.600000000000001e-06"/>
    </inertial>
  </link>
  <gazebo reference="RF_foot_fixed">
    <disableFixedJointLumping>true</disableFixedJointLumping>
  </gazebo>
  <gazebo reference="Rabad_Link">
    <mu1>0.2</mu1>
    <mu2>0.2</mu2>
    <material>Gazebo/DarkGrey</material>
  </gazebo>
  <gazebo reference="Rhip_Link">
    <mu1>0.2</mu1>
    <mu2>0.2</mu2>
    <self_collide>0</self_collide>
    <material>Gazebo/DarkGrey</material>
    <kp value="1000000.0"/>
    <kd value="100.0"/>
  </gazebo>
  <gazebo reference="Rknee_Link">
    <mu1>0.6</mu1>
    <mu2>0.6</mu2>
    <self_collide>1</self_collide>
  </gazebo>
  <gazebo reference="RF_FOOT">
    <mu1>0.6</mu1>
    <mu2>0.6</mu2>
    <self_collide>1</self_collide>
    <material>Gazebo/DarkGrey</material>
    <kp value="1000000.0"/>
    <kd value="100.0"/>
  </gazebo>
  <transmission name="RF_HAA_tran">
    <type>transmission_interface/SimpleTransmission</type>
    <joint name="Joint_Rabad">
      <hardwareInterface>hardware_interface/EffortJointInterface</hardwareInterface>
    </joint>
    <actuator name="RF_HAA_motor">
      <hardwareInterface>hardware_interface/EffortJointInterface</hardwareInterface>
      <mechanicalReduction>1</mechanicalReduction>
    </actuator>
  </transmission>
  <transmission name="RF_HFE_tran">
    <type>transmission_interface/SimpleTransmission</type>
    <joint name="Joint_Rhip">
      <hardwareInterface>hardware_interface/EffortJointInterface</hardwareInterface>
    </joint>
    <actuator name="RF_HFE_motor">
      <hardwareInterface>hardware_interface/EffortJointInterface</hardwareInterface>
      <mechanicalReduction>1</mechanicalReduction>
    </actuator>
  </transmission>
  <transmission name="RF_KFE_tran">
    <type>transmission_interface/SimpleTransmission</type>
    <joint name="Joint_Rknee">
      <hardwareInterface>hardware_interface/EffortJointInterface</hardwareInterface>
    </joint>
    <actuator name="RF_KFE_motor">
      <hardwareInterface>hardware_interface/EffortJointInterface</hardwareInterface>
      <mechanicalReduction>1</mechanicalReduction>
    </actuator>
  </transmission>

  <link
    name="LF_hip_Link">
    <inertial>
      <origin
        xyz="0.071586 -0.00061306 -0.049078"
        rpy="0 0 0" />
      <mass
        value="0.17708" />
      <inertia
        ixx="0.00025"
        ixy="-0.00001"
        ixz="0.00028"
        iyy="0.00070"
        iyz="0.00000"
        izz="0.00046" />
    </inertial>
    <visual>
      <origin
        xyz="0 0 0"
        rpy="0 0 0" />
      <geometry>
        <mesh
          filename="package://wheel_legged_description/meshes_display/LF_hip_Link.STL" />
      </geometry>
      <material
        name="">
        <color
          rgba="1 1 1 1" />
      </material>
    </visual>
    <collision>
      <origin
        xyz="0 0 0"
        rpy="0 0 0" />
      <geometry>
        <mesh
          filename="package://wheel_legged_description/meshes_display/LF_hip_Link.STL" />
      </geometry>
    </collision>
  </link>
  <joint
    name="Joint_LFhip"
    type="revolute">
    <origin
      xyz="0.073188 -0.18444 0.10042"
      rpy="1.5708 0 0" />
    <parent
      link="base_link" />
    <child
      link="LF_hip_Link" />
    <axis
      xyz="0 1 0" />
    <limit
      lower="0"
      upper="0"
      effort="0"
      velocity="0" />
  </joint>
  <link
    name="LF_knee_Link">
    <inertial>
      <origin
        xyz="-0.087992 0.0069897 -0.098088"
        rpy="0 0 0" />
      <mass
        value="0.22064" />
      <inertia
        ixx="0.0012527"
        ixy="1.3325E-07"
        ixz="-0.0010382"
        iyy="0.0022498"
        iyz="1.5085E-07"
        izz="0.0010024" />
    </inertial>
    <visual>
      <origin
        xyz="0 0 0"
        rpy="0 0 0" />
      <geometry>
        <mesh
          filename="package://wheel_legged_description/meshes_display/LF_knee_Link.STL" />
      </geometry>
      <material
        name="">
        <color
          rgba="1 1 1 1" />
      </material>
    </visual>
    <collision>
      <origin
        xyz="0 0 0"
        rpy="0 0 0" />
      <geometry>
        <mesh
          filename="package://wheel_legged_description/meshes_display/LF_knee_Link.STL" />
      </geometry>
    </collision>
  </link>
  <joint
    name="Joint_LFknee"
    type="revolute">
    <origin
      xyz="0.124 0.00618 -0.084704"
      rpy="0 0 0" />
    <parent
      link="LF_hip_Link" />
    <child
      link="LF_knee_Link" />
    <axis
      xyz="0 -1 0" />
    <limit
      lower="0"
      upper="0"
      effort="0"
      velocity="0" />
  </joint>
  <link name="laxis">
    <inertial>
      <origin xyz="-3.0131E-05 -0.011025 4.8139E-05" rpy="0 0 0"/>
      <mass
        value="0.001" />
      <inertia
        ixx="0.000000001"
        ixy="0.000000001"
        ixz="0.000000001"
        iyy="0.000000001"
        iyz="0.000000001"
        izz="0.000000001" />
    </inertial>
    <visual>
      <origin
        xyz="0 0 0"
        rpy="0 1.5707963 0" />
      <geometry>
        <cylinder radius="0.005" length="0.05"/>  
      </geometry>
      <material
        name="">
        <color
          rgba="0 0 0 1" />
      </material>
    </visual>
  </link>
  <joint
    name="Joint_laxis"
    type="fixed">
    <origin
      xyz="-0.17978 0.0402 -0.20147"
      rpy="0 0 0" />
    <parent
      link="LF_knee_Link" />
    <child
      link="laxis" />
  </joint>
  <joint dont_collapse="true" name="LH_foot_fixed" type="fixed">
    <origin rpy="0 0 0" xyz="0 0 0"/>
    <parent link="laxis"/>
    <child link="LH_FOOT"/>
  </joint>
  <link name="LH_FOOT">
    <visual>
      <origin rpy="0 0 0" xyz="0 0 0"/>
      <geometry>
        <sphere radius="0.01"/>
      </geometry>
      <material name=""/>
    </visual>
    <collision>
      <origin rpy="0 0 0" xyz="0 0 0"/>
      <geometry>
        <sphere radius="0.01"/>
      </geometry>
    </collision>
    <inertial>
      <mass value="0.06"/>
      <inertia ixx="9.600000000000001e-06" ixy="0.0" ixz="0.0" iyy="9.600000000000001e-06" iyz="0.0" izz="9.600000000000001e-06"/>
    </inertial>
  </link>
  <link
    name="Lwheel_Link">
    <inertial>
      <origin
        xyz="-3.0131E-05 -0.011025 4.8139E-05"
        rpy="0 0 0" />
      <mass
        value="0.82507" />
      <inertia
        ixx="0.00076"
        ixy="-7.5079E-08"
        ixz="-2.5154E-08"
        iyy="0.00098684"
        iyz="-4.764E-08"
        izz="0.00076" />
    </inertial>
    <visual>
      <origin
        xyz="0 0 0"
        rpy="0 0 0" />
      <geometry>
        <mesh
          filename="package://wheel_legged_description/meshes_display/Lwheel_Link.STL" />
      </geometry>
      <material
        name="">
        <color
          rgba="0.79216 0.81961 0.93333 1" />
      </material>
    </visual>
    <collision>
      <origin
        xyz="0 0 0"
        rpy="0 0 0" />
      <geometry>
        <mesh
          filename="package://wheel_legged_description/meshes_display/Lwheel_Link.STL" />
      </geometry>
    </collision>
  </link>
  <joint
    name="Joint_LWheel"
    type="continuous">
    <origin
      xyz="0 0 0"
      rpy="0 0 0" />
    <parent
      link="laxis" />
    <child
      link="Lwheel_Link" />
    <axis
      xyz="0 1 0" />
  </joint>
  <link
    name="LB_hip_Link">
    <inertial>
      <origin
        xyz="-0.12071 -0.0034121 -0.088742"
        rpy="0 0 0" />
      <mass
        value="0.18" />
      <inertia
        ixx="0.00003"
        ixy="7.3917E-11"
        ixz="-5.8848E-10"
        iyy="0.00002"
        iyz="-4.7929E-11"
        izz="0.00003" />
    </inertial>
    <visual>
      <origin
        xyz="0 0 0"
        rpy="0 0 0" />
      <geometry>
        <mesh
          filename="package://wheel_legged_description/meshes_display/LB_hip_Link.STL" />
      </geometry>
      <material
        name="">
        <color
          rgba="1 1 1 1" />
      </material>
    </visual>
    <collision>
      <origin
        xyz="0 0 0"
        rpy="0 0 0" />
      <geometry>
        <mesh
          filename="package://wheel_legged_description/meshes_display/LB_hip_Link.STL" />
      </geometry>
    </collision>
  </link>
  <joint
    name="Joint_LBhip"
    type="revolute">
    <origin
      xyz="-0.046812 -0.18381 0.10342"
      rpy="1.5708 0 0" />
    <parent
      link="base_link" />
    <child
      link="LB_hip_Link" />
    <axis
      xyz="0 -1 0" />
    <limit
      lower="0"
      upper="0"
      effort="0"
      velocity="0" />
  </joint>
  <link
    name="LB_knee_Link">
    <inertial>
      <origin
        xyz="0.091245 -0.007 -0.097323"
        rpy="0 0 0" />
      <mass
        value="0.22512" />
      <inertia
        ixx="0.0012034"
        ixy="4.344E-10"
        ixz="0.0010689"
        iyy="0.0022544"
        iyz="-2.101E-10"
        izz="0.0010564" />
    </inertial>
    <visual>
      <origin
        xyz="0 0 0"
        rpy="0 0 0" />
      <geometry>
        <mesh
          filename="package://wheel_legged_description/meshes_display/LB_knee_Link.STL" />
      </geometry>
      <material
        name="">
        <color
          rgba="1 1 1 1" />
      </material>
    </visual>
    <collision>
      <origin
        xyz="0 0 0"
        rpy="0 0 0" />
      <geometry>
        <mesh
          filename="package://wheel_legged_description/meshes_display/LB_knee_Link.STL" />
      </geometry>
    </collision>
  </link>
  <joint
    name="Joint_LBknee"
    type="revolute">
    <origin
      xyz="-0.12071 -0.00732 -0.08874"
      rpy="0 0 0" />
    <parent
      link="LB_hip_Link" />
    <child
      link="LB_knee_Link" />
    <axis
      xyz="0 -1 0" />
    <limit
      lower="0"
      upper="0"
      effort="0"
      velocity="0" />
  </joint>

  <gazebo reference="LH_foot_fixed">
    <disableFixedJointLumping>true</disableFixedJointLumping>
  </gazebo>
  <gazebo reference="LF_hip_Link">
    <mu1>0.2</mu1>
    <mu2>0.2</mu2>
    <material>Gazebo/DarkGrey</material>
  </gazebo>
  <gazebo reference="LB_hip_Link">
    <mu1>0.2</mu1>
    <mu2>0.2</mu2>
    <self_collide>0</self_collide>
    <material>Gazebo/DarkGrey</material>
    <kp value="1000000.0"/>
    <kd value="100.0"/>
  </gazebo>
  <gazebo reference="Lwheel_Link">
    <mu1>0.6</mu1>
    <mu2>0.6</mu2>
    <self_collide>1</self_collide>
  </gazebo>
  <gazebo reference="LH_FOOT">
    <mu1>0.6</mu1>
    <mu2>0.6</mu2>
    <self_collide>1</self_collide>
    <material>Gazebo/DarkGrey</material>
    <kp value="1000000.0"/>
    <kd value="100.0"/>
  </gazebo>
  <transmission name="LH_HAA_tran">
    <type>transmission_interface/SimpleTransmission</type>
    <joint name="Joint_LFhip">
      <hardwareInterface>hardware_interface/EffortJointInterface</hardwareInterface>
    </joint>
    <actuator name="LH_HAA_motor">
      <hardwareInterface>hardware_interface/EffortJointInterface</hardwareInterface>
      <mechanicalReduction>1</mechanicalReduction>
    </actuator>
  </transmission>
  <transmission name="LH_HFE_tran">
    <type>transmission_interface/SimpleTransmission</type>
    <joint name="Joint_LBhip">
      <hardwareInterface>hardware_interface/EffortJointInterface</hardwareInterface>
    </joint>
    <actuator name="LH_HFE_motor">
      <hardwareInterface>hardware_interface/EffortJointInterface</hardwareInterface>
      <mechanicalReduction>1</mechanicalReduction>
    </actuator>
  </transmission>
  <transmission name="LH_KFE_tran">
    <type>transmission_interface/SimpleTransmission</type>
    <joint name="Joint_LWheel">
      <hardwareInterface>hardware_interface/EffortJointInterface</hardwareInterface>
    </joint>
    <actuator name="LH_KFE_motor">
      <hardwareInterface>hardware_interface/EffortJointInterface</hardwareInterface>
      <mechanicalReduction>1</mechanicalReduction>
    </actuator>
  </transmission>

  <link
    name="RF_hip_Link">
    <inertial>
      <origin
        xyz="0.072085 0.00079307 -0.047706"
        rpy="0 0 0" />
      <mass
        value="0.17708" />
      <inertia
        ixx="0.00024"
        ixy="0.00001"
        ixz="0.00027"
        iyy="0.00070"
        iyz="1.1622E-07"
        izz="0.00047" />
    </inertial>
    <visual>
      <origin
        xyz="0 0 0"
        rpy="0 0 0" />
      <geometry>
        <mesh
          filename="package://wheel_legged_description/meshes_display/RF_hip_Link.STL" />
      </geometry>
      <material
        name="">
        <color
          rgba="1 1 1 1" />
      </material>
    </visual>
    <collision>
      <origin
        xyz="0 0 0"
        rpy="0 0 0" />
      <geometry>
        <mesh
          filename="package://wheel_legged_description/meshes_display/RF_hip_Link.STL" />
      </geometry>
    </collision>
  </link>
  <joint
    name="Joint_RFhip"
    type="revolute">
    <origin
      xyz="0.073188 -0.18381 -0.2774"
      rpy="1.5708 0 0" />
    <parent
      link="base_link" />
    <child
      link="RF_hip_Link" />
    <axis
      xyz="0 1 0" />
    <limit
      lower="0"
      upper="0"
      effort="0"
      velocity="0" />
  </joint>
  <link
    name="RF_knee_Link">
    <inertial>
      <origin
        xyz="-0.087617 -0.0069897 -0.098431"
        rpy="0 0 0" />
      <mass
        value="0.22064" />
      <inertia
        ixx="0.0012366"
        ixy="-1.3498E-07"
        ixz="-0.00104"
        iyy="0.0022498"
        iyz="-1.493E-07"
        izz="0.0010185" />
    </inertial>
    <visual>
      <origin
        xyz="0 0 0"
        rpy="0 0 0" />
      <geometry>
        <mesh
          filename="package://wheel_legged_description/meshes_display/RF_knee_Link.STL" />
      </geometry>
      <material
        name="">
        <color
          rgba="1 1 1 1" />
      </material>
    </visual>
    <collision>
      <origin
        xyz="0 0 0"
        rpy="0 0 0" />
      <geometry>
        <mesh
          filename="package://wheel_legged_description/meshes_display/RF_knee_Link.STL" />
      </geometry>
    </collision>
  </link>
  <joint
    name="Joint_RFknee"
    type="revolute">
    <origin
      xyz="0.12479 -0.006 -0.082902"
      rpy="0 0 0" />
    <parent
      link="RF_hip_Link" />
    <child
      link="RF_knee_Link" />
    <axis
      xyz="0 1 0" />
    <limit
      lower="0"
      upper="0"
      effort="0"
      velocity="0" />
  </joint>
  <link name="raxis">
    <inertial>
      <origin xyz="5.4339E-05 0.011025 -1.65E-05" rpy="0 0 0"/>
      <mass
        value="0.001" />
      <inertia
        ixx="0.000000001"
        ixy="0.000000001"
        ixz="0.000000001"
        iyy="0.000000001"
        iyz="0.000000001"
        izz="0.000000001" />
    </inertial>
    <visual>
      <origin
        xyz="0 0 0"
        rpy="0 1.5707963 0" />
      <geometry>
        <cylinder radius="0.005" length="0.05"/>  
      </geometry>
      <material
        name="">
        <color
          rgba="0 0 0 1" />
      </material>
    </visual>
  </link>
  <joint
    name="Joint_raxis"
    type="fixed">
    <origin
      xyz="-0.18007 -0.0402 -0.20123"
      rpy="0 0 0" />
    <parent
      link="RF_knee_Link" />
    <child
      link="raxis" />
  </joint>
  <joint dont_collapse="true" name="RH_foot_fixed" type="fixed">
    <origin rpy="0 0 0" xyz="0 0 0"/>
    <parent link="RB_knee_Link"/>
    <child link="RH_FOOT"/>
  </joint>
  <link name="RH_FOOT">
    <visual>
      <origin rpy="0 0 0" xyz="0 0 0"/>
      <geometry>
        <sphere radius="0.01"/>
      </geometry>
      <material name=""/>
    </visual>
    <collision>
      <origin rpy="0 0 0" xyz="0 0 0"/>
      <geometry>
        <sphere radius="0.01"/>
      </geometry>
    </collision>
    <inertial>
      <mass value="0.06"/>
      <inertia ixx="9.600000000000001e-06" ixy="0.0" ixz="0.0" iyy="9.600000000000001e-06" iyz="0.0" izz="9.600000000000001e-06"/>
    </inertial>
  </link>
  <link
    name="Rwheel_Link">
    <inertial>
      <origin
        xyz="5.4339E-05 0.011025 -1.65E-05"
        rpy="0 0 0" />
      <mass
        value="0.82507" />
      <inertia
        ixx="0.00076"
        ixy="2.6377E-08"
        ixz="3.8194E-08"
        iyy="0.00098684"
        iyz="8.4895E-08"
        izz="0.00076" />
    </inertial>
    <visual>
      <origin
        xyz="0 0 0"
        rpy="0 0 0" />
      <geometry>
        <mesh
          filename="package://wheel_legged_description/meshes_display/Rwheel_Link.STL" />
      </geometry>
      <material
        name="">
        <color
          rgba="0.79216 0.81961 0.93333 1" />
      </material>
    </visual>
    <collision>
      <origin
        xyz="0 0 0"
        rpy="0 0 0" />
      <geometry>
        <mesh
          filename="package://wheel_legged_description/meshes_display/Rwheel_Link.STL" />
      </geometry>
    </collision>
  </link>
  <joint
    name="Joint_RWheel"
    type="contiuous">
    <origin
      xyz="0 0 0"
      rpy="0 0 0" />
    <parent
      link="raxis" />
    <child
      link="Rwheel_Link" />
    <axis
      xyz="0 1 0" />
  </joint>
  <link
    name="RB_hip_Link">
    <inertial>
      <origin
        xyz="0 0 0"
        rpy="0 0 0" />
      <mass
        value="0.18" />
      <inertia
        ixx="0.00003"
        ixy="0"
        ixz="0.00000"
        iyy="0.00002"
        iyz="0"
        izz="0.00003" />
    </inertial>
    <visual>
      <origin
        xyz="0 0 0"
        rpy="0 0 0" />
      <geometry>
        <mesh
          filename="package://wheel_legged_description/meshes_display/RB_hip_Link.STL" />
      </geometry>
      <material
        name="">
        <color
          rgba="1 1 1 1" />
      </material>
    </visual>
    <collision>
      <origin
        xyz="0 0 0"
        rpy="0 0 0" />
      <geometry>
        <mesh
          filename="package://wheel_legged_description/meshes_display/RB_hip_Link.STL" />
      </geometry>
    </collision>
  </link>
  <joint
    name="Joint_RBhip"
    type="revolute">
    <origin
      xyz="-0.046812 -0.18445 -0.2804"
      rpy="1.5708 0 0" />
    <parent
      link="base_link" />
    <child
      link="RB_hip_Link" />
    <axis
      xyz="0 1 0" />
    <limit
      lower="0"
      upper="0"
      effort="0"
      velocity="0" />
  </joint>
  <link
    name="RB_knee_Link">
    <inertial>
      <origin
        xyz="0.091931 0.007 -0.096666"
        rpy="0 0 0" />
      <mass
        value="0.22512" />
      <inertia
        ixx="0.0011792"
        ixy="-1.8436E-10"
        ixz="0.0010703"
        iyy="0.0022544"
        iyz="4.462E-10"
        izz="0.0010806" />
    </inertial>
    <visual>
      <origin
        xyz="0 0 0"
        rpy="0 0 0" />
      <geometry>
        <mesh
          filename="package://wheel_legged_description/meshes_display/RB_knee_Link.STL" />
      </geometry>
      <material
        name="">
        <color
          rgba="1 1 1 1" />
      </material>
    </visual>
    <collision>
      <origin
        xyz="0 0 0"
        rpy="0 0 0" />
      <geometry>
        <mesh
          filename="package://wheel_legged_description/meshes_display/RB_knee_Link.STL" />
      </geometry>
    </collision>
  </link>
  <joint
    name="Joint_RBknee"
    type="revolute">
    <origin
      xyz="-0.12105 0.0075 -0.088911"
      rpy="0 0 0" />
    <parent
      link="RB_hip_Link" />
    <child
      link="RB_knee_Link" />
    <axis
      xyz="0 1 0" />
    <limit
      lower="0"
      upper="0"
      effort="0"
      velocity="0" />
  </joint>

  <gazebo reference="RH_foot_fixed">
    <disableFixedJointLumping>true</disableFixedJointLumping>
  </gazebo>
  <gazebo reference="RF_hip_Link">
    <mu1>0.2</mu1>
    <mu2>0.2</mu2>
    <material>Gazebo/DarkGrey</material>
  </gazebo>
  <gazebo reference="RB_hip_Link">
    <mu1>0.2</mu1>
    <mu2>0.2</mu2>
    <self_collide>0</self_collide>
    <material>Gazebo/DarkGrey</material>
    <kp value="1000000.0"/>
    <kd value="100.0"/>
  </gazebo>
  <gazebo reference="Rwheel_Link">
    <mu1>0.6</mu1>
    <mu2>0.6</mu2>
    <self_collide>1</self_collide>
  </gazebo>
  <gazebo reference="RH_FOOT">
    <mu1>0.6</mu1>
    <mu2>0.6</mu2>
    <self_collide>1</self_collide>
    <material>Gazebo/DarkGrey</material>
    <kp value="1000000.0"/>
    <kd value="100.0"/>
  </gazebo>
  <transmission name="RH_HAA_tran">
    <type>transmission_interface/SimpleTransmission</type>
    <joint name="Joint_RFhip">
      <hardwareInterface>hardware_interface/EffortJointInterface</hardwareInterface>
    </joint>
    <actuator name="RH_HAA_motor">
      <hardwareInterface>hardware_interface/EffortJointInterface</hardwareInterface>
      <mechanicalReduction>1</mechanicalReduction>
    </actuator>
  </transmission>
  <transmission name="RH_HFE_tran">
    <type>transmission_interface/SimpleTransmission</type>
    <joint name="Joint_RBhip">
      <hardwareInterface>hardware_interface/EffortJointInterface</hardwareInterface>
    </joint>
    <actuator name="RH_HFE_motor">
      <hardwareInterface>hardware_interface/EffortJointInterface</hardwareInterface>
      <mechanicalReduction>1</mechanicalReduction>
    </actuator>
  </transmission>
  <transmission name="RH_KFE_tran">
    <type>transmission_interface/SimpleTransmission</type>
    <joint name="Joint_RWheel">
      <hardwareInterface>hardware_interface/EffortJointInterface</hardwareInterface>
    </joint>
    <actuator name="RH_KFE_motor">
      <hardwareInterface>hardware_interface/EffortJointInterface</hardwareInterface>
      <mechanicalReduction>1</mechanicalReduction>
    </actuator>
  </transmission>

  <gazebo>
    <plugin name="Myrobot_ClosedLoopPlugin" filename="libpegasus_gazebo_closed_loop_plugin.so">
      <joint>Joint_laxis</joint>
      <child>LB_knee_Link</child>
      <parent>laxis</parent>
      <position>0.00 0.00 0.00</position>
      <rotation>0.00 -0.00 0.00</rotation>
    </plugin>
  </gazebo>

  <gazebo>
    <plugin name="Myrobot_ClosedLoopPlugin" filename="libpegasus_gazebo_closed_loop_plugin.so">
      <joint>Joint_raxis</joint>
      <child>RB_knee_Link</child>
      <parent>raxis</parent>
      <position>0.00 0.00 0.00</position>
      <rotation>0.00 -0.00 0.00</rotation>
    </plugin>
  </gazebo>
</robot>