<?xml version="1.0" encoding="utf-8"?>
<!-- This URDF was automatically created by SolidWorks to URDF Exporter! Originally created by Stephen Brawner (brawner@gmail.com) 
     Commit Version: 1.6.0-4-g7f85cfe  Build Version: 1.6.7995.38578
     For more information, please see http://wiki.ros.org/sw_urdf_exporter -->
<robot
  name="Wheel_legged_repair2">
  <gazebo>
    <plugin filename="libwheel_legged_hw_sim.so" name="gazebo_ros_control">
      <robotNamespace>/</robotNamespace>
      <robotParam>wheel_legged_description</robotParam>
      <robotSimType>ocs2/wheel_legged/LeggedHWSim</robotSimType>
    </plugin>
  </gazebo>
  <gazebo>
    <plugin filename="libgazebo_ros_p3d.so" name="p3d_base_controller">
      <alwaysOn>true</alwaysOn>
      <updateRate>1000.0</updateRate>
      <bodyName>base_link</bodyName>
      <topicName>ground_truth/state</topicName>
      <gaussianNoise>0</gaussianNoise>
      <frameName>world</frameName>
      <xyzOffsets>0 0 0</xyzOffsets>
      <rpyOffsets>0 0 0</rpyOffsets>
    </plugin>
  </gazebo>
  <link name="dummy_link">
    </link>
  <joint name="dummy_to_base_link" type="fixed">
    <parent link="dummy_link"/>
    <child link="base_link"/>
    <origin rpy="0 0 0" xyz="0 0 0"/>
  </joint>
  <link
    name="base_link">
    <inertial>
      <origin
        xyz="-0.0315927041891579 0.00071509554661818 0.0289337663641155"
        rpy="0 0 0" />
      <mass
        value="14.2740" />
      <inertia
        ixx="0.27466"
        ixy="0.00296"
        ixz="0.00836"
        iyy="0.13446"
        iyz="0.00133"
        izz="0.29099" />
    </inertial>
    <visual>
      <origin
        xyz="0 0 0"
        rpy="0 0 0" />
      <geometry>
        <mesh
          filename="package://wheel_legged_description/meshes_display/base_link.STL" />
      </geometry>
      <material
        name="">
        <color
          rgba="0.529411764705882 0.549019607843137 0.549019607843137 1" />
      </material>
    </visual>
    <collision>
      <origin
        xyz="0 0 0.02"
        rpy="0 0 0" />
      <geometry>
        <box size="0.28 0.33 0.213" />
      </geometry>
    </collision>
  </link>
  <joint name="base_imu_joint" type="fixed">
    <origin rpy="0. 0. 0." xyz="0. 0. 0."/>
    <parent link="base_link"/>
    <child link="base_imu"/>
  </joint>
  <!-- Imu link -->
  <link name="base_imu">
    <inertial>
      <mass value="0.01"/>
      <origin rpy="0 0 0" xyz="0 0 0"/>
      <inertia ixx="0.000001" ixy="0" ixz="0" iyy="0.000001" iyz="0" izz="0.000001"/>
    </inertial>
    <visual>
      <origin rpy="0 0 0" xyz="0 0 0"/>
      <geometry>
        <box size="0.015 0.015 0.004"/>
      </geometry>
    </visual>
    <material name="orange">
      <color rgba="255 108 10 255"/>
    </material>
  </link>
  <gazebo reference="base_imu">
    <material>Gazebo/Orange</material>
  </gazebo>
  <gazebo reference="base_imu_joint">
    <disableFixedJointLumping>true</disableFixedJointLumping>
  </gazebo>
  <link
    name="waist_Link">
    <inertial>
      <origin
        xyz="0.31833503254984 -0.00588440380564897 -0.0148208364273254"
        rpy="0 0 0" />
      <mass
        value="2.98" />
      <inertia
        ixx="0.02232"
        ixy="0.00027"
        ixz="0.00628"
        iyy="0.08653"
        iyz="-0.00002"
        izz="0.10216" />
    </inertial>
    <visual>
      <origin
        xyz="0 0 0"
        rpy="0 0 0" />
      <geometry>
        <mesh
          filename="package://wheel_legged_description/meshes_display/waist_Link.STL" />
      </geometry>
      <material
        name="">
        <color
          rgba="0.792156862745098 0.819607843137255 0.933333333333333 1" />
      </material>
    </visual>
    <collision>
      <origin
        xyz="0.28 0 0"
        rpy="0 0 0" />
      <geometry>
        <box size="0.56 0.24 0.1" />
      </geometry>
    </collision>
  </link>
  <joint
    name="Joint_waist"
    type="fixed">
    <origin
      xyz="0.000107023903053843 0.00535894473094398 0.0709154080084677"
      rpy="0 0 0" />
    <parent
      link="base_link" />
    <child
      link="waist_Link" />
  </joint>
  <link
    name="Labad_Link">
    <inertial>
      <origin
        xyz="-0.0059568735538047 -0.0107941359948864 -0.000171965598623203"
        rpy="0 0 0" />
      <mass
        value="1.27" />
      <inertia
        ixx="0.00270"
        ixy="0.00002"
        ixz="0.00000"
        iyy="0.00162"
        iyz="-0.00001"
        izz="0.00284" />
    </inertial>
    <visual>
      <origin
        xyz="0 0 0"
        rpy="0 0 0" />
      <geometry>
        <mesh
          filename="package://wheel_legged_description/meshes_display/Labad_Link.STL" />
      </geometry>
      <material
        name="">
        <color
          rgba="0.792156862745098 0.819607843137255 0.933333333333333 1" />
      </material>
    </visual>
    <collision>
      <origin
        xyz="0 0 0"
        rpy="1.57 0 0" />
      <geometry>
        <cylinder length="0.13" radius="0.048" />
      </geometry>
    </collision>
  </link>
  <joint
    name="Joint_Labad"
    type="revolute">
    <origin
      xyz="0.560072609936946 0.10042568308067 -0.0377386746004073"
      rpy="0 0 0" />
    <parent
      link="waist_Link" />
    <child
      link="Labad_Link" />
    <axis
      xyz="1 0 0" />
    <limit
      lower="-0.424"
      upper="1.04"
      effort="24.206"
      velocity="30" />
  </joint>
  <link
    name="Lhip_Link">
    <inertial>
      <origin
        xyz="-0.000723234483344437 -0.0046042090863776 -0.0865057935300157"
        rpy="0 0 0" />
      <mass
        value="1.02" />
      <inertia
        ixx="0.00953"
        ixy="0.00000"
        ixz="-0.00005"
        iyy="0.00994"
        iyz="0.00039"
        izz="0.00079" />
    </inertial>
    <visual>
      <origin
        xyz="0 0 0"
        rpy="0 0 0" />
      <geometry>
        <mesh
          filename="package://wheel_legged_description/meshes_display/Lhip_Link.STL" />
      </geometry>
      <material
        name="">
        <color
          rgba="0.792156862745098 0.819607843137255 0.933333333333333 1" />
      </material>
    </visual>
    <collision>
      <origin
        xyz="0 0 -0.115"
        rpy="0 0 0" />
      <geometry>
        <cylinder length="0.23" radius="0.05" />
      </geometry>
    </collision>
  </link>
  <joint
    name="Joint_Lhip"
    type="revolute">
    <origin
      xyz="-0.000174442927638796 0.0776923012893297 0.000193909756050659"
      rpy="0 0 0" />
    <parent
      link="Labad_Link" />
    <child
      link="Lhip_Link" />
    <axis
      xyz="0 1 0" />
    <limit
      lower="-0.503"
      upper="1.41"
      effort="22.76"
      velocity="30" />
  </joint>
  <link
    name="Lknee_Link">
    <inertial>
      <origin
        xyz="-0.00170647439577776 -0.0006724224018545 -0.146092965502694"
        rpy="0 0 0" />
      <mass
        value="0.18" />
      <inertia
        ixx="0.00159"
        ixy="0.00000"
        ixz="-0.00002"
        iyy="0.00159"
        iyz="0.00005"
        izz="0.00003" />
    </inertial>
    <visual>
      <origin
        xyz="0 0 0"
        rpy="0 0 0" />
      <geometry>
        <mesh
          filename="package://wheel_legged_description/meshes_display/Lknee_Link.STL" />
      </geometry>
      <material
        name="">
        <color
          rgba="0.792156862745098 0.819607843137255 0.933333333333333 1" />
      </material>
    </visual>
    <collision>
      <origin
        xyz="0 0 -0.125"
        rpy="0 0 0" />
      <geometry>
        <cylinder length="0.25" radius="0.04" />
      </geometry>
    </collision>
  </link>
  <joint
    name="Joint_Lknee"
    type="revolute">
    <origin
      xyz="-0.00165861871548567 0.03140703662 -0.23004781996907"
      rpy="0 0 0" />
    <parent
      link="Lhip_Link" />
    <child
      link="Lknee_Link" />
    <axis
      xyz="0 1 0" />
    <limit
      lower="-3.14"
      upper="0"
      effort="28"
      velocity="30" />
  </joint>

  <joint dont_collapse="true" name="LF_foot_fixed" type="fixed">
    <origin rpy="0 0 0" xyz="-0.0025 0.002 -0.232"/>
    <parent link="Lknee_Link"/>
    <child link="LF_FOOT"/>
  </joint>
  <link name="LF_FOOT">
    <visual>
      <origin rpy="0 0 0" xyz="0 0 0"/>
      <geometry>
        <sphere radius="0.02"/>
      </geometry>
      <material name=""/>
    </visual>
    <collision>
      <origin rpy="0 0 0" xyz="0 0 0"/>
      <geometry>
        <sphere radius="0.02"/>
      </geometry>
    </collision>
    <inertial>
      <mass value="0.06"/>
      <inertia ixx="9.600000000000001e-06" ixy="0.0" ixz="0.0" iyy="9.600000000000001e-06" iyz="0.0" izz="9.600000000000001e-06"/>
    </inertial>
  </link>
  <gazebo reference="LF_foot_fixed">
    <disableFixedJointLumping>true</disableFixedJointLumping>
  </gazebo>
  <gazebo reference="Labad_Link">
    <mu1>0.2</mu1>
    <mu2>0.2</mu2>
    <material>Gazebo/DarkGrey</material>
  </gazebo>
  <gazebo reference="Lhip_Link">
    <mu1>0.2</mu1>
    <mu2>0.2</mu2>
    <self_collide>0</self_collide>
    <material>Gazebo/DarkGrey</material>
    <kp value="1000000.0"/>
    <kd value="100.0"/>
  </gazebo>
  <gazebo reference="Lknee_Link">
    <mu1>0.6</mu1>
    <mu2>0.6</mu2>
    <self_collide>1</self_collide>
  </gazebo>
  <gazebo reference="LF_FOOT">
    <mu1>0.6</mu1>
    <mu2>0.6</mu2>
    <self_collide>1</self_collide>
    <material>Gazebo/DarkGrey</material>
    <kp value="1000000.0"/>
    <kd value="100.0"/>
  </gazebo>

  <transmission name="LF_HAA_tran">
    <type>transmission_interface/SimpleTransmission</type>
    <joint name="Joint_Labad">
      <hardwareInterface>hardware_interface/EffortJointInterface</hardwareInterface>
    </joint>
    <actuator name="LF_HAA_motor">
      <hardwareInterface>hardware_interface/EffortJointInterface</hardwareInterface>
      <mechanicalReduction>1</mechanicalReduction>
    </actuator>
  </transmission>
  <transmission name="LF_HFE_tran">
    <type>transmission_interface/SimpleTransmission</type>
    <joint name="Joint_Lhip">
      <hardwareInterface>hardware_interface/EffortJointInterface</hardwareInterface>
    </joint>
    <actuator name="LF_HFE_motor">
      <hardwareInterface>hardware_interface/EffortJointInterface</hardwareInterface>
      <mechanicalReduction>1</mechanicalReduction>
    </actuator>
  </transmission>
  <transmission name="LF_KFE_tran">
    <type>transmission_interface/SimpleTransmission</type>
    <joint name="Joint_Lknee">
      <hardwareInterface>hardware_interface/EffortJointInterface</hardwareInterface>
    </joint>
    <actuator name="LF_KFE_motor">
      <hardwareInterface>hardware_interface/EffortJointInterface</hardwareInterface>
      <mechanicalReduction>1</mechanicalReduction>
    </actuator>
  </transmission>

  <link
    name="Rabad_Link">
    <inertial>
      <origin
        xyz="-0.00605931973669505 0.0107734945712203 0.000594365938715979"
        rpy="0 0 0" />
      <mass
        value="1.27" />
      <inertia
        ixx="0.00270"
        ixy="-0.00002"
        ixz="0.00000"
        iyy="0.00162"
        iyz="0.00001"
        izz="0.00284" />
    </inertial>
    <visual>
      <origin
        xyz="0 0 0"
        rpy="0 0 0" />
      <geometry>
        <mesh
          filename="package://wheel_legged_description/meshes_display/Rabad_Link.STL" />
      </geometry>
      <material
        name="">
        <color
          rgba="0.792156862745098 0.819607843137255 0.933333333333333 1" />
      </material>
    </visual>
    <collision>
      <origin
        xyz="0 0 0"
        rpy="1.57 0 0" />
      <geometry>
        <cylinder length="0.13" radius="0.048" />
      </geometry>
    </collision>
  </link>
  <joint
    name="Joint_Rabad"
    type="revolute">
    <origin
      xyz="0.559972609936946 -0.113109069230096 -0.0392386745963477"
      rpy="0 0 0" />
    <parent
      link="waist_Link" />
    <child
      link="Rabad_Link" />
    <axis
      xyz="1 0 0" />
    <limit
      lower="-1.04"
      upper="0.424"
      effort="24.206"
      velocity="30" />
  </joint>
  <link
    name="Rhip_Link">
    <inertial>
      <origin
        xyz="-0.000328070545023595 0.00342241500343016 -0.0865491802752725"
        rpy="0 0 0" />
      <mass
        value="1.02" />
      <inertia
        ixx="0.00953"
        ixy="0.00000"
        ixz="-0.00005"
        iyy="0.00994"
        iyz="-0.00041"
        izz="0.00079" />
    </inertial>
    <visual>
      <origin
        xyz="0 0 0"
        rpy="0 0 0" />
      <geometry>
        <mesh
          filename="package://wheel_legged_description/meshes_display/Rhip_Link.STL" />
      </geometry>
      <material
        name="">
        <color
          rgba="0.792156862745098 0.819607843137255 0.933333333333333 1" />
      </material>
    </visual>
    <collision>
      <origin
        xyz="0 0 -0.115"
        rpy="0 0 0" />
      <geometry>
        <cylinder length="0.23" radius="0.05" />
      </geometry>
    </collision>
  </link>
  <joint
    name="Joint_Rhip"
    type="revolute">
    <origin
      xyz="-7.14113841855379E-05 -0.0767142451699043 0.000899684818292834"
      rpy="0 0 0" />
    <parent
      link="Rabad_Link" />
    <child
      link="Rhip_Link" />
    <axis
      xyz="0 1 0" />
    <limit
      lower="-0.503"
      upper="1.41"
      effort="22.76"
      velocity="30" />
  </joint>
  <link
    name="Rknee_Link">
    <inertial>
      <origin
        xyz="-0.004592774342979 -0.000135154398930304 -0.146286475047147"
        rpy="0 0 0" />
      <mass
        value="0.18" />
      <inertia
        ixx="0.00159"
        ixy="0.00000"
        ixz="-0.00005"
        iyy="0.00159"
        iyz="-0.00005"
        izz="0.00003" />
    </inertial>
    <visual>
      <origin
        xyz="0 0 0"
        rpy="0 0 0" />
      <geometry>
        <mesh
          filename="package://wheel_legged_description/meshes_display/Rknee_Link.STL" />
      </geometry>
      <material
        name="">
        <color
          rgba="0.792156862745098 0.819607843137255 0.933333333333333 1" />
      </material>
    </visual>
    <collision>
      <origin
        xyz="0 0 -0.125"
        rpy="0 0 0" />
      <geometry>
        <cylinder length="0.25" radius="0.04" />
      </geometry>
    </collision>
  </link>
  <joint
    name="Joint_Rknee"
    type="revolute">
    <origin
      xyz="-0.00114049819299789 -0.03238909343 -0.229761642984864"
      rpy="0 0 0" />
    <parent
      link="Rhip_Link" />
    <child
      link="Rknee_Link" />
    <axis
      xyz="0 1 0" />
    <limit
      lower="-3.14"
      upper="0"
      effort="28"
      velocity="30" />
  </joint>
  <joint dont_collapse="true" name="RF_foot_fixed" type="fixed">
    <origin rpy="0 0 0" xyz="-0.007 -0.002 -0.232"/>
    <parent link="Rknee_Link"/>
    <child link="RF_FOOT"/>
  </joint>
  <link name="RF_FOOT">
    <visual>
      <origin rpy="0 0 0" xyz="0 0 0"/>
      <geometry>
        <sphere radius="0.02"/>
      </geometry>
      <material name=""/>
    </visual>
    <collision>
      <origin rpy="0 0 0" xyz="0 0 0"/>
      <geometry>
        <sphere radius="0.02"/>
      </geometry>
    </collision>
    <inertial>
      <mass value="0.06"/>
      <inertia ixx="9.600000000000001e-06" ixy="0.0" ixz="0.0" iyy="9.600000000000001e-06" iyz="0.0" izz="9.600000000000001e-06"/>
    </inertial>
  </link>
  <gazebo reference="RF_foot_fixed">
    <disableFixedJointLumping>true</disableFixedJointLumping>
  </gazebo>
  <gazebo reference="Rabad_Link">
    <mu1>0.2</mu1>
    <mu2>0.2</mu2>
    <material>Gazebo/DarkGrey</material>
  </gazebo>
  <gazebo reference="Rhip_Link">
    <mu1>0.2</mu1>
    <mu2>0.2</mu2>
    <self_collide>0</self_collide>
    <material>Gazebo/DarkGrey</material>
    <kp value="1000000.0"/>
    <kd value="100.0"/>
  </gazebo>
  <gazebo reference="Rknee_Link">
    <mu1>0.6</mu1>
    <mu2>0.6</mu2>
    <self_collide>1</self_collide>
  </gazebo>
  <gazebo reference="RF_FOOT">
    <mu1>0.6</mu1>
    <mu2>0.6</mu2>
    <self_collide>1</self_collide>
    <material>Gazebo/DarkGrey</material>
    <kp value="1000000.0"/>
    <kd value="100.0"/>
  </gazebo>
  <transmission name="RF_HAA_tran">
    <type>transmission_interface/SimpleTransmission</type>
    <joint name="Joint_Rabad">
      <hardwareInterface>hardware_interface/EffortJointInterface</hardwareInterface>
    </joint>
    <actuator name="RF_HAA_motor">
      <hardwareInterface>hardware_interface/EffortJointInterface</hardwareInterface>
      <mechanicalReduction>1</mechanicalReduction>
    </actuator>
  </transmission>
  <transmission name="RF_HFE_tran">
    <type>transmission_interface/SimpleTransmission</type>
    <joint name="Joint_Rhip">
      <hardwareInterface>hardware_interface/EffortJointInterface</hardwareInterface>
    </joint>
    <actuator name="RF_HFE_motor">
      <hardwareInterface>hardware_interface/EffortJointInterface</hardwareInterface>
      <mechanicalReduction>1</mechanicalReduction>
    </actuator>
  </transmission>
  <transmission name="RF_KFE_tran">
    <type>transmission_interface/SimpleTransmission</type>
    <joint name="Joint_Rknee">
      <hardwareInterface>hardware_interface/EffortJointInterface</hardwareInterface>
    </joint>
    <actuator name="RF_KFE_motor">
      <hardwareInterface>hardware_interface/EffortJointInterface</hardwareInterface>
      <mechanicalReduction>1</mechanicalReduction>
    </actuator>
  </transmission>
  <link
    name="LF_hip_Link">
    <inertial>
      <origin
        xyz="0.0715859473019776 -0.000613057937742634 -0.0490776481210589"
        rpy="0 0 0" />
      <mass
        value="0.177077351601831" />
      <inertia
        ixx="0.00025"
        ixy="-0.00001"
        ixz="0.00028"
        iyy="0.00070"
        iyz="0.00000"
        izz="0.00046" />
    </inertial>
    <visual>
      <origin
        xyz="0 0 0"
        rpy="0 0 0" />
      <geometry>
        <mesh
          filename="package://wheel_legged_description/meshes_display/LF_hip_Link.STL" />
      </geometry>
      <material
        name="">
        <color
          rgba="1 1 1 1" />
      </material>
    </visual>
    <collision>
      <origin
        xyz="0.06 0 -0.04"
        rpy="0 0.60 0" />
      <geometry>
        <box size="0.2 0.02 0.05"/>
      </geometry>
    </collision>
  </link>
  <joint
    name="Joint_LFhip"
    type="revolute">
    <origin
      xyz="0.0601110073096042 0.191428944730944 0.0692325389969545"
      rpy="0 0 0" />
    <parent
      link="base_link" />
    <child
      link="LF_hip_Link" />
    <axis
      xyz="0 1 0" />
    <limit
      lower="-0.93"
      upper="0.45"
      effort="100"
      velocity="30" />
  </joint>
  <link
    name="LF_knee_Link">
    <inertial>
      <origin
        xyz="-0.0879917500835232 0.00698974587289122 -0.0980884731139554"
        rpy="0 0 0" />
      <mass
        value="0.220636590729618" />
      <inertia
        ixx="0.00125267041946443"
        ixy="1.33246159780275E-07"
        ixz="0.00103815405803474"
        iyy="0.00224978424446147"
        iyz="1.5084856807172E-07"
        izz="0.0010024000146733" />
    </inertial>
    <visual>
      <origin
        xyz="0 0 0"
        rpy="0 0 0" />
      <geometry>
        <mesh
          filename="package://wheel_legged_description/meshes_display/LF_knee_Link.STL" />
      </geometry>
      <material
        name="">
        <color
          rgba="1 1 1 1" />
      </material>
    </visual>
    <collision>
      <origin
        xyz="0 0 0"
        rpy="0 0 0" />
      <geometry>
        <mesh
          filename="package://wheel_legged_description/meshes_display/LF_knee_Link.STL" />
      </geometry>
    </collision>
  </link>
  <joint
    name="Joint_LFknee"
    type="continuous">
    <origin
      xyz="0.124002084415241 0.00617999999999999 -0.0847036935476426"
      rpy="0 0 0" />
    <parent
      link="LF_hip_Link" />
    <child
      link="LF_knee_Link" />
    <axis
      xyz="0 1 0" />
    <limit
      effort="100"
      velocity="30" />
  </joint>
  <!-- <link name="LH_FOOT_axis">
    <inertial>
      <origin
        xyz="-3.0131E-05 -0.011025 4.8139E-05"
        rpy="0 0 0" />
      <mass
        value="0.001" />
      <inertia
        ixx="0.000000001"
        ixy="0.000000001"
        ixz="0.000000001"
        iyy="0.000000001"
        iyz="0.000000001"
        izz="0.000000001" />
    </inertial>
  </link>
  <joint 
    name="LH_FOOT_pos"
    type="fixed">
    <origin
      xyz="-0.17978 0.0402 -0.20147"
      rpy="0 0 0"/>
    <parent
      link="LF_knee_Link" />
    <child
      link="LH_FOOT_axis" />
  </joint> -->
  <link name="laxis">
    <inertial>
      <origin
        xyz="-3.0131E-05 -0.011025 4.8139E-05"
        rpy="0 0 0" />
      <mass
        value="0.001" />
      <inertia
        ixx="0.000000001"
        ixy="0.000000001"
        ixz="0.000000001"
        iyy="0.000000001"
        iyz="0.000000001"
        izz="0.000000001" />
    </inertial>
    <visual>
      <origin
        xyz="0 -0.045 0"
        rpy="0 1.5707963 1.5707963" />
      <geometry>
        <cylinder radius="0.005" length="0.05"/>  
      </geometry>
      <material
        name="">
        <color
          rgba="0 0 0 1" />
      </material>
    </visual>
  </link>
  <joint
    name="Joint_laxis"
    type="continuous">
    <origin
      xyz="-0.17978 0.0402 -0.20147"
      rpy="0 0 0"/>
    <parent
      link="LF_knee_Link" />
    <child
      link="laxis" />
    <axis
      xyz="0 1 0" />
    <limit
      effort="100"
      velocity="30" />
  </joint>
  <joint dont_collapse="true" name="LH_foot_fixed" type="fixed">
    <origin rpy="0 0 0" xyz="-0.18 0.04 -0.27"/>
    <parent link="LF_knee_Link"/>
    <child link="LH_FOOT"/>
  </joint>
  <link name="LH_FOOT">
    <visual>
      <origin rpy="0 0 0" xyz="0 0 0"/>
      <geometry>
        <sphere radius="0.02"/>
      </geometry>
      <material name=""/>
    </visual>
    <collision>
      <origin rpy="0 0 0" xyz="0 0 0"/>
      <geometry>
        <sphere radius="0.02"/>
      </geometry>
    </collision>
    <inertial>
      <mass value="0.06"/>
      <inertia ixx="9.600000000000001e-06" ixy="0.0" ixz="0.0" iyy="9.600000000000001e-06" iyz="0.0" izz="9.600000000000001e-06"/>
    </inertial>
  </link>
  <link
    name="Lwheel_Link">
    <inertial>
      <origin
        xyz="0 0 0"
        rpy="0 0 0" />
      <mass
        value="1.225067339568551" />
      <inertia
        ixx="0.0014368"
        ixy="-0.0000001"
        ixz="0.00000"
        iyy="0.0010985"
        iyz="-0.0000002"
        izz="0.0010987" />
    </inertial>
    <visual>
      <origin
        xyz="0 0 0"
        rpy="0 0 0" />
      <geometry>
        <mesh
          filename="package://wheel_legged_description/meshes_display/Lwheel_Link.STL" />
      </geometry>
      <material
        name="">
        <color
          rgba="0.792156862745098 0.819607843137255 0.933333333333333 1" />
      </material>
    </visual>
    <collision>
      <origin
        xyz="0 0 0"
        rpy="1.57 0 0" />
      <geometry>
        <cylinder radius="0.085" length="0.04"/>
      </geometry>
    </collision>
  </link>
  <joint
    name="Joint_LWheel"
    type="revolute">
    <origin
      xyz="0 0 0"
      rpy="0 0 0" />
    <parent
      link="laxis" />
    <child
      link="Lwheel_Link" />
    <axis
      xyz="0 1 0" />
    <limit
      lower="0"
      upper="0"
      effort="100"
      velocity="30" />
  </joint>
  <link
    name="LB_hip_Link">
    <inertial>
      <origin
        xyz="-0.120705431995635 -0.0034120517742835 -0.0887419692390345"
        rpy="0 0 0" />
      <mass
        value="0.18" />
      <inertia
        ixx="0.00003"
        ixy="7.3917E-11"
        ixz="-5.8848E-10"
        iyy="0.00002"
        iyz="-4.7929E-11"
        izz="0.00003" />
    </inertial>
    <visual>
      <origin
        xyz="0 0 0"
        rpy="0 0 0" />
      <geometry>
        <mesh
          filename="package://wheel_legged_description/meshes_display/LB_hip_Link.STL" />
      </geometry>
      <material
        name="">
        <color
          rgba="1 1 1 1" />
      </material>
    </visual>
    <collision>
      <origin
        xyz="0 0 0"
        rpy="0 0 0" />
      <geometry>
        <mesh
          filename="package://wheel_legged_description/meshes_display/LB_hip_Link.STL" />
      </geometry>
    </collision>
  </link>
  <joint
    name="Joint_LBhip"
    type="revolute">
    <origin
      xyz="-0.0598896717289598 0.194428944730944 0.068607253265332"
      rpy="0 0 0" />
    <parent
      link="base_link" />
    <child
      link="LB_hip_Link" />
    <axis
      xyz="0 1 0" />
    <limit
      lower="-0.45"
      upper="0.93"
      effort="100"
      velocity="30" />
  </joint>
  <link
    name="LB_knee_Link">
    <inertial>
      <origin
        xyz="0.0912449552358761 -0.00700003329445006 -0.0973229658683606"
        rpy="0 0 0" />
      <mass
        value="0.225120563239333" />
      <inertia
        ixx="0.0012034431480915"
        ixy="4.343972488372E-10"
        ixz="0.00106891333882648"
        iyy="0.00225441651432823"
        iyz="-2.1009592482083E-10"
        izz="0.00105637636039267" />
    </inertial>
    <visual>
      <origin
        xyz="0 0 0"
        rpy="0 0 0" />
      <geometry>
        <mesh
          filename="package://wheel_legged_description/meshes_display/LB_knee_Link.STL" />
      </geometry>
      <material
        name="">
        <color
          rgba="1 1 1 1" />
      </material>
    </visual>
    <collision>
      <origin
        xyz="0 0 0"
        rpy="0 0 0" />
      <geometry>
        <mesh
          filename="package://wheel_legged_description/meshes_display/LB_knee_Link.STL" />
      </geometry>
    </collision>
  </link>
  <joint
    name="Joint_LBknee"
    type="continuous">
    <origin
      xyz="-0.120708306533441 -0.00731999999587096 -0.088740397586716"
      rpy="0 0 0" />
    <parent
      link="LB_hip_Link" />
    <child
      link="LB_knee_Link" />
    <axis
      xyz="0 1 0" />
    <limit
      effort="100"
      velocity="30" />
  </joint>

  <gazebo reference="LH_foot_fixed">
    <disableFixedJointLumping>true</disableFixedJointLumping>
  </gazebo>
  <gazebo reference="LF_hip_Link">
    <mu1>0.5</mu1>
    <mu2>0.5</mu2>
    <material>Gazebo/DarkGrey</material>
  </gazebo>
  <gazebo reference="LB_hip_Link">
    <mu1>0.5</mu1>
    <mu2>0.5</mu2>
    <self_collide>0</self_collide>
    <material>Gazebo/DarkGrey</material>
    <kp value="1000000.0"/>
    <kd value="100.0"/>
  </gazebo>
  <gazebo reference="Lwheel_Link">
    <mu1>1</mu1>
    <mu2>1</mu2>
    <self_collide>1</self_collide>
  </gazebo>
  <gazebo reference="LH_FOOT">
    <mu1>0.6</mu1>
    <mu2>0.6</mu2>
    <self_collide>1</self_collide>
    <material>Gazebo/DarkGrey</material>
    <kp value="1000000.0"/>
    <kd value="100.0"/>
  </gazebo>
  <transmission name="LH_HAA_tran">
    <type>transmission_interface/SimpleTransmission</type>
    <joint name="Joint_LFhip">
      <hardwareInterface>hardware_interface/EffortJointInterface</hardwareInterface>
    </joint>
    <actuator name="LH_HAA_motor">
      <hardwareInterface>hardware_interface/EffortJointInterface</hardwareInterface>
      <mechanicalReduction>1</mechanicalReduction>
    </actuator>
  </transmission>
  <transmission name="LH_HFE_tran">
    <type>transmission_interface/SimpleTransmission</type>
    <joint name="Joint_LBhip">
      <hardwareInterface>hardware_interface/EffortJointInterface</hardwareInterface>
    </joint>
    <actuator name="LH_HFE_motor">
      <hardwareInterface>hardware_interface/EffortJointInterface</hardwareInterface>
      <mechanicalReduction>1</mechanicalReduction>
    </actuator>
  </transmission>
  <transmission name="LH_KFE_tran">
    <type>transmission_interface/SimpleTransmission</type>
    <joint name="Joint_LWheel">
      <hardwareInterface>hardware_interface/EffortJointInterface</hardwareInterface>
    </joint>
    <actuator name="LH_KFE_motor">
      <hardwareInterface>hardware_interface/EffortJointInterface</hardwareInterface>
      <mechanicalReduction>1</mechanicalReduction>
    </actuator>
  </transmission>
  <link
    name="RF_hip_Link">
    <inertial>
      <origin
        xyz="0.0720853679381507 0.000793069219928833 -0.047705511647015"
        rpy="0 0 0" />
      <mass
        value="0.17707713097992" />
      <inertia
        ixx="0.00024"
        ixy="0.00001"
        ixz="0.00027"
        iyy="0.00070"
        iyz="1.1622E-07"
        izz="0.00047" />
    </inertial>
    <visual>
      <origin
        xyz="0 0 0"
        rpy="0 0 0" />
      <geometry>
        <mesh
          filename="package://wheel_legged_description/meshes_display/RF_hip_Link.STL" />
      </geometry>
      <material
        name="">
        <color
          rgba="1 1 1 1" />
      </material>
    </visual>
    <collision>
      <origin
        xyz="0 0 0"
        rpy="0 0 0" />
      <geometry>
        <mesh
          filename="package://wheel_legged_description/meshes_display/RF_hip_Link.STL" />
      </geometry>
    </collision>
  </link>
  <joint
    name="Joint_RFhip"
    type="revolute">
    <origin
      xyz="0.0601108731781712 -0.186391055269056 0.0686016436558831"
      rpy="0 0 0" />
    <parent
      link="base_link" />
    <child
      link="RF_hip_Link" />
    <axis
      xyz="0 1 0" />
    <limit
      lower="-0.93"
      upper="0.45"
      effort="100"
      velocity="30" />
  </joint>
  <link
    name="RF_knee_Link">
    <inertial>
      <origin
        xyz="-0.0876168385301678 -0.00698974586358514 -0.098431126850286"
        rpy="0 0 0" />
      <mass
        value="0.220636564220652" />
      <inertia
        ixx="0.00123658340346104"
        ixy="-1.34979068507616E-07"
        ixz="-0.00103996649234408"
        iyy="0.00224978360491325"
        iyz="-1.49299991935938E-07"
        izz="0.00101848639074699" />
    </inertial>
    <visual>
      <origin
        xyz="0 0 0"
        rpy="0 0 0" />
      <geometry>
        <mesh
          filename="package://wheel_legged_description/meshes_display/RF_knee_Link.STL" />
      </geometry>
      <material
        name="">
        <color
          rgba="1 1 1 1" />
      </material>
    </visual>
    <collision>
      <origin
        xyz="0 0 0"
        rpy="0 0 0" />
      <geometry>
        <mesh
          filename="package://wheel_legged_description/meshes_display/RF_knee_Link.STL" />
      </geometry>
    </collision>
  </link>
  <joint
    name="Joint_RFknee"
    type="continuous">
    <origin
      xyz="0.124790770494982 -0.00600000000000001 -0.0829023604540317"
      rpy="0 0 0" />
    <parent
      link="RF_hip_Link" />
    <child
      link="RF_knee_Link" />
    <axis
      xyz="0 1 0" />
    <limit
      effort="100"
      velocity="30" />
  </joint>
  <!-- <link name="RH_FOOT_axis">
    <inertial>
      <origin
        xyz="5.4339E-05 0.011025 -1.65E-05"
        rpy="0 0 0" />
      <mass
        value="0.001" />
      <inertia
        ixx="0.000000001"
        ixy="0.000000001"
        ixz="0.000000001"
        iyy="0.000000001"
        iyz="0.000000001"
        izz="0.000000001" />
    </inertial>
  </link>
  <joint 
    name="RH_FOOT_pos"
    type="fixed">
    <origin
      xyz="-0.180074686761231 -0.0402 -0.201230183724276"
      rpy="0 0 0"/>
    <parent
      link="RF_knee_Link" />
    <child
      link="RH_FOOT_axis" />
  </joint> -->
  <link name="raxis">
    <inertial>
      <origin 
        xyz="5.4339E-05 0.011025 -1.65E-05"
        rpy="0 0 0" />
      <mass
        value="0.001" />
      <inertia
        ixx="0.000000001"
        ixy="0.000000001"
        ixz="0.000000001"
        iyy="0.000000001"
        iyz="0.000000001"
        izz="0.000000001" />
    </inertial>
    <visual>
      <origin
        xyz="0 0.045 0"
        rpy="0 1.5707963 1.5707963" />
      <geometry>
        <cylinder radius="0.005" length="0.05"/>  
      </geometry>
      <material
        name="">
        <color
          rgba="0 0 0 1" />
      </material>
    </visual>
  </link>
  <joint
    name="Joint_raxis"
    type="continuous">
    <origin
      xyz="-0.180074686761231 -0.0402 -0.201230183724276"
      rpy="0 0 0"/>
    <parent
      link="RF_knee_Link" />
    <child
      link="raxis" />
    <axis
      xyz="0 1 0" />
    <limit
      effort="100"
      velocity="30" />
  </joint>
  
  <joint dont_collapse="true" name="RH_foot_fixed" type="fixed">
    <origin rpy="0 0 0" xyz="-0.18 -0.04 -0.27"/>
    <parent link="RF_knee_Link"/>
    <child link="RH_FOOT"/>
  </joint>
  <link name="RH_FOOT">
    <visual>
      <origin rpy="0 0 0" xyz="0 0 0"/>
      <geometry>
        <sphere radius="0.02"/>
      </geometry>
      <material name=""/>
    </visual>
    <collision>
      <origin rpy="0 0 0" xyz="0 0 0"/>
      <geometry>
        <sphere radius="0.02"/>
      </geometry>
    </collision>
    <inertial>
      <mass value="0.06"/>
      <inertia ixx="9.600000000000001e-06" ixy="0.0" ixz="0.0" iyy="9.600000000000001e-06" iyz="0.0" izz="9.600000000000001e-06"/>
    </inertial>
  </link>
  <link
    name="Rwheel_Link">
    <inertial>
      <origin
        xyz="0 0 0"
        rpy="0 0 0" />
      <mass
        value="1.225067339568551" />
      <inertia
        ixx="0.0014368"
        ixy="-0.0000001"
        ixz="0.00000"
        iyy="0.0010985"
        iyz="-0.0000002"
        izz="0.0010987" />
    </inertial>
    <visual>
      <origin
        xyz="0 0 0"
        rpy="0 0 0" />
      <geometry>
        <mesh
          filename="package://wheel_legged_description/meshes_display/Rwheel_Link.STL" />
      </geometry>
      <material
        name="">
        <color
          rgba="0.792156862745098 0.819607843137255 0.933333333333333 1" />
      </material>
    </visual>
    <collision>
      <origin
        xyz="0 0 0"
        rpy="0 0 0" />
      <geometry>
        <mesh
          filename="package://wheel_legged_description/meshes_display/Rwheel_Link.STL" />
      </geometry>
    </collision>
  </link>
  <joint
    name="Joint_RWheel"
    type="revolute">
    <origin
      xyz="0 0 0"
      rpy="0 0 0" />
    <parent
      link="raxis" />
    <child
      link="Rwheel_Link" />
    <axis
      xyz="0 1 0" />
    <limit
      lower="0"
      upper="0"
      effort="100"
      velocity="30" />
  </joint>
  <link
    name="RB_hip_Link">
    <inertial>
      <origin
        xyz="-0.12105125340948 0.00359177541416372 -0.088907033663831"
        rpy="0 0 0" />
      <mass
        value="0.18" />
      <inertia
        ixx="0.00003"
        ixy="0"
        ixz="0.00000"
        iyy="0.00002"
        iyz="0"
        izz="0.00003" />
    </inertial>
    <visual>
      <origin
        xyz="0 0 0"
        rpy="0 0 0" />
      <geometry>
        <mesh
          filename="package://wheel_legged_description/meshes_display/RB_hip_Link.STL" />
      </geometry>
      <material
        name="">
        <color
          rgba="1 1 1 1" />
      </material>
    </visual>
    <collision>
      <origin
        xyz="0 0 0"
        rpy="0 0 0" />
      <geometry>
        <mesh
          filename="package://wheel_legged_description/meshes_display/RB_hip_Link.STL" />
      </geometry>
    </collision>
  </link>
  <joint
    name="Joint_RBhip"
    type="revolute">
    <origin
      xyz="-0.0598896998936048 -0.189391055269056 0.0692431889167757"
      rpy="0 0 0" />
    <parent
      link="base_link" />
    <child
      link="RB_hip_Link" />
    <axis
      xyz="0 1 0" />
    <limit
      lower="-0.45"
      upper="0.93"
      effort="100"
      velocity="30" />
  </joint>
  <link
    name="RB_knee_Link">
    <inertial>
      <origin
        xyz="0.0919309000618504 0.00700003329444926 -0.0966663306720594"
        rpy="0 0 0" />
      <mass
        value="0.225120559665859" />
      <inertia
        ixx="0.00117918932813021"
        ixy="-1.84362849788354E-10"
        ixz="0.00107030572889462"
        iyy="0.0022544164735451"
        iyz="4.46199131705546E-10"
        izz="0.00108063013951937" />
    </inertial>
    <visual>
      <origin
        xyz="0 0 0"
        rpy="0 0 0" />
      <geometry>
        <mesh
          filename="package://wheel_legged_description/meshes_display/RB_knee_Link.STL" />
      </geometry>
      <material
        name="">
        <color
          rgba="1 1 1 1" />
      </material>
    </visual>
    <collision>
      <origin
        xyz="0 0 0"
        rpy="0 0 0" />
      <geometry>
        <mesh
          filename="package://wheel_legged_description/meshes_display/RB_knee_Link.STL" />
      </geometry>
    </collision>
  </link>
  <joint
    name="Joint_RBknee"
    type="continuous">
    <origin
      xyz="-0.121050541990562 0.00750000000412893 -0.0889105126724281"
      rpy="0 0 0" />
    <parent
      link="RB_hip_Link" />
    <child
      link="RB_knee_Link" />
    <axis
      xyz="0 1 0" />
    <limit
      effort="100"
      velocity="30" />
  </joint>
  <gazebo reference="RH_foot_fixed">
    <disableFixedJointLumping>true</disableFixedJointLumping>
  </gazebo>
  <gazebo reference="RF_hip_Link">
    <mu1>0.5</mu1>
    <mu2>0.5</mu2>
    <material>Gazebo/DarkGrey</material>
  </gazebo>
  <gazebo reference="RB_hip_Link">
    <mu1>0.5</mu1>
    <mu2>0.5</mu2>
    <self_collide>0</self_collide>
    <material>Gazebo/DarkGrey</material>
    <kp value="1000000.0"/>
    <kd value="100.0"/>
  </gazebo>
  <gazebo reference="Rwheel_Link">
    <mu1>1</mu1>
    <mu2>1</mu2>
    <self_collide>1</self_collide>
  </gazebo>
  <gazebo reference="RH_FOOT">
    <mu1>0.6</mu1>
    <mu2>0.6</mu2>
    <self_collide>1</self_collide>
    <material>Gazebo/DarkGrey</material>
    <kp value="1000000.0"/>
    <kd value="100.0"/>
  </gazebo>
  <transmission name="RH_HAA_tran">
    <type>transmission_interface/SimpleTransmission</type>
    <joint name="Joint_RFhip">
      <hardwareInterface>hardware_interface/EffortJointInterface</hardwareInterface>
    </joint>
    <actuator name="RH_HAA_motor">
      <hardwareInterface>hardware_interface/EffortJointInterface</hardwareInterface>
      <mechanicalReduction>1</mechanicalReduction>
    </actuator>
  </transmission>
  <transmission name="RH_HFE_tran">
    <type>transmission_interface/SimpleTransmission</type>
    <joint name="Joint_RBhip">
      <hardwareInterface>hardware_interface/EffortJointInterface</hardwareInterface>
    </joint>
    <actuator name="RH_HFE_motor">
      <hardwareInterface>hardware_interface/EffortJointInterface</hardwareInterface>
      <mechanicalReduction>1</mechanicalReduction>
    </actuator>
  </transmission>
  <transmission name="RH_KFE_tran">
    <type>transmission_interface/SimpleTransmission</type>
    <joint name="Joint_RWheel">
      <hardwareInterface>hardware_interface/EffortJointInterface</hardwareInterface>
    </joint>
    <actuator name="RH_KFE_motor">
      <hardwareInterface>hardware_interface/EffortJointInterface</hardwareInterface>
      <mechanicalReduction>1</mechanicalReduction>
    </actuator>
  </transmission>
  <gazebo>
    <plugin name="Myrobot_ClosedLoopPlugin" filename="libpegasus_gazebo_closed_loop_plugin.so">
      <joint>Joint_laxis</joint>
      <child>laxis</child>
      <parent>LB_knee_Link</parent>
      <position>0.00 0.00 0.00</position>
      <rotation>0.00 -0.00 0.00</rotation>
    </plugin>
  </gazebo>
  <gazebo>
    <plugin name="Myrobot_ClosedLoopPlugin" filename="libpegasus_gazebo_closed_loop_plugin.so">
      <joint>Joint_raxis</joint>
      <child>raxis</child>
      <parent>RB_knee_Link</parent>
      <position>0.00 0.00 0.00</position>
      <rotation>0.00 -0.00 0.00</rotation>
    </plugin>
  </gazebo>
</robot>
